Workbook

Sheet วิธีใช้
A1: เทมเพลตรายรับรายจ่าย
A2: บันทึกรายการ → ดูสรุปรายเดือนและเทียบงบประมาณได้อัตโนมัติ
A4: ขั้นตอน
A5: 1. ตั้งค่า | B5: ไปที่ชีต ‘ตั้งค่า’ ใส่ปีที่ต้องการสรุป ยอดเงินคงเหลือยกมา แก้ชื่อหมวดหมู่และงบประมาณต่อเดือนได้ตามต้องการ
A6: 2. บันทึก | B6: ไปที่ชีต ‘บันทึก’ กรอก วันที่ / รายการ / หมวดหมู่ (เลือกจากรายการ) / จำนวนเงิน — ประเภทรายรับหรือรายจ่ายจะขึ้นเองตามหมวดหมู่
A7: 3. สรุป | B7: ชีต ‘สรุปรายเดือน’ และ ‘งบประมาณ’ คำนวณให้อัตโนมัติ ไม่ต้องแก้สูตร
A8: 4. ตัวอย่าง | B8: แถวที่ 5–14 ในชีต ‘บันทึก’ เป็นข้อมูลตัวอย่าง ลบออกได้เลย (เลือกเซลล์ A–G แล้วกด Delete — อย่าลบทั้งแถว)
A10: สัญลักษณ์สีเซลล์
A11: ตัวอักษรสีน้ำเงิน บนพื้นเหลืองอ่อน | B11: ช่องสำหรับกรอกข้อมูล
A12: ตัวอักษรสีดำ | B12: สูตรคำนวณ — ไม่ต้องแก้
A13: ตัวอักษรสีเขียว | B13: ค่าที่ดึงมาจากชีตอื่น
A15: หมายเหตุ
A16: • จำนวนเงิน | B16: ใส่เป็นบวกเสมอ ทั้งรายรับและรายจ่าย ระบบแยกเองตามหมวดหมู่
A17: • จำนวนแถว | B17: เตรียมสูตรไว้ 1,000 รายการ (แถว 5–1004) หากต้องการมากกว่านี้ ให้คัดลอกแถวสุดท้ายลงไปต่อ
A18: • ปี | B18: ชีตสรุปนับเฉพาะรายการในปีที่ตั้งไว้ในชีต ‘ตั้งค่า’ ใช้ปี ค.ศ. เช่น 2026 (= พ.ศ. 2569)

Sheet ตั้งค่า
A1: ตั้งค่า
A2: แก้ได้เฉพาะช่องพื้นเหลือง
A3: ปีที่สรุป (ค.ศ.) | B3: 2026 | C3: ปี พ.ศ. | D3: =B3+543 -> 2569
A4: ยอดคงเหลือยกมา (฿) | B4: 15000
A5: กรอกต่อกันจากบนลงล่าง ไม่เว้นแถวว่าง
A6: หมวดหมู่รายรับ | C6: หมวดหมู่รายจ่าย | D6: งบต่อเดือน (฿) | F6: ช่องทางชำระ | H6: รายการหมวดหมู่ทั้งหมด (อัตโนมัติ)
A7: เงินเดือน | C7: อาหาร & เครื่องดื่ม | D7: 6000 | F7: เงินสด | H7: =IF(ROWS($H$7:H7)<=COUNTA($A$7:$A$18),INDEX($A$7:$A$18,ROWS($H$7:H7)),IF(ROWS($H$7:H7)-COUNTA($A$7:$A$18)<=COUNTA($C$7:$C$31),INDEX($C$7:$C$31,ROWS($H$7:H7)-COUNTA($A$7:$A$18)),"")) -> เงินเดือน
A8: โบนัส | C8: ที่พัก / ค่าเช่า | D8: 8000 | F8: โอน / พร้อมเพย์ | H8: =IF(ROWS($H$7:H8)<=COUNTA($A$7:$A$18),INDEX($A$7:$A$18,ROWS($H$7:H8)),IF(ROWS($H$7:H8)-COUNTA($A$7:$A$18)<=COUNTA($C$7:$C$31),INDEX($C$7:$C$31,ROWS($H$7:H8)-COUNTA($A$7:$A$18)),"")) -> โบนัส
A9: รายได้เสริม / ฟรีแลนซ์ | C9: ค่าน้ำ ค่าไฟ ค่าเน็ต | D9: 1500 | F9: บัตรเดบิต | H9: =IF(ROWS($H$7:H9)<=COUNTA($A$7:$A$18),INDEX($A$7:$A$18,ROWS($H$7:H9)),IF(ROWS($H$7:H9)-COUNTA($A$7:$A$18)<=COUNTA($C$7:$C$31),INDEX($C$7:$C$31,ROWS($H$7:H9)-COUNTA($A$7:$A$18)),"")) -> รายได้เสริม / ฟรีแลนซ์
A10: ขายของ | C10: เดินทาง / น้ำมัน | D10: 2500 | F10: บัตรเครดิต | H10: =IF(ROWS($H$7:H10)<=COUNTA($A$7:$A$18),INDEX($A$7:$A$18,ROWS($H$7:H10)),IF(ROWS($H$7:H10)-COUNTA($A$7:$A$18)<=COUNTA($C$7:$C$31),INDEX($C$7:$C$31,ROWS($H$7:H10)-COUNTA($A$7:$A$18)),"")) -> ขายของ
A11: ดอกเบี้ย / เงินปันผล | C11: ช้อปปิ้ง | D11: 2000 | F11: e-Wallet | H11: =IF(ROWS($H$7:H11)<=COUNTA($A$7:$A$18),INDEX($A$7:$A$18,ROWS($H$7:H11)),IF(ROWS($H$7:H11)-COUNTA($A$7:$A$18)<=COUNTA($C$7:$C$31),INDEX($C$7:$C$31,ROWS($H$7:H11)-COUNTA($A$7:$A$18)),"")) -> ดอกเบี้ย / เงินปันผล
A12: เงินคืน / ของขวัญ | C12: สุขภาพ & ประกัน | D12: 1000 | H12: =IF(ROWS($H$7:H12)<=COUNTA($A$7:$A$18),INDEX($A$7:$A$18,ROWS($H$7:H12)),IF(ROWS($H$7:H12)-COUNTA($A$7:$A$18)<=COUNTA($C$7:$C$31),INDEX($C$7:$C$31,ROWS($H$7:H12)-COUNTA($A$7:$A$18)),"")) -> เงินคืน / ของขวัญ
A13: รายรับอื่น ๆ | C13: การศึกษา | D13: 500 | H13: =IF(ROWS($H$7:H13)<=COUNTA($A$7:$A$18),INDEX($A$7:$A$18,ROWS($H$7:H13)),IF(ROWS($H$7:H13)-COUNTA($A$7:$A$18)<=COUNTA($C$7:$C$31),INDEX($C$7:$C$31,ROWS($H$7:H13)-COUNTA($A$7:$A$18)),"")) -> รายรับอื่น ๆ
C14: บันเทิง & สมาชิกรายเดือน | D14: 800 | H14: =IF(ROWS($H$7:H14)<=COUNTA($A$7:$A$18),INDEX($A$7:$A$18,ROWS($H$7:H14)),IF(ROWS($H$7:H14)-COUNTA($A$7:$A$18)<=COUNTA($C$7:$C$31),INDEX($C$7:$C$31,ROWS($H$7:H14)-COUNTA($A$7:$A$18)),"")) -> อาหาร & เครื่องดื่ม
C15: ครอบครัว | D15: 2000 | H15: =IF(ROWS($H$7:H15)<=COUNTA($A$7:$A$18),INDEX($A$7:$A$18,ROWS($H$7:H15)),IF(ROWS($H$7:H15)-COUNTA($A$7:$A$18)<=COUNTA($C$7:$C$31),INDEX($C$7:$C$31,ROWS($H$7:H15)-COUNTA($A$7:$A$18)),"")) -> ที่พัก / ค่าเช่า
C16: ผ่อนชำระ / หนี้ | D16: 3000 | H16: =IF(ROWS($H$7:H16)<=COUNTA($A$7:$A$18),INDEX($A$7:$A$18,ROWS($H$7:H16)),IF(ROWS($H$7:H16)-COUNTA($A$7:$A$18)<=COUNTA($C$7:$C$31),INDEX($C$7:$C$31,ROWS($H$7:H16)-COUNTA($A$7:$A$18)),"")) -> ค่าน้ำ ค่าไฟ ค่าเน็ต
C17: ออม & ลงทุน | D17: 5000 | H17: =IF(ROWS($H$7:H17)<=COUNTA($A$7:$A$18),INDEX($A$7:$A$18,ROWS($H$7:H17)),IF(ROWS($H$7:H17)-COUNTA($A$7:$A$18)<=COUNTA($C$7:$C$31),INDEX($C$7:$C$31,ROWS($H$7:H17)-COUNTA($A$7:$A$18)),"")) -> เดินทาง / น้ำมัน
C18: ทำบุญ / ของขวัญ | D18: 500 | H18: =IF(ROWS($H$7:H18)<=COUNTA($A$7:$A$18),INDEX($A$7:$A$18,ROWS($H$7:H18)),IF(ROWS($H$7:H18)-COUNTA($A$7:$A$18)<=COUNTA($C$7:$C$31),INDEX($C$7:$C$31,ROWS($H$7:H18)-COUNTA($A$7:$A$18)),"")) -> ช้อปปิ้ง
C19: รายจ่ายอื่น ๆ | D19: 1000 | H19: =IF(ROWS($H$7:H19)<=COUNTA($A$7:$A$18),INDEX($A$7:$A$18,ROWS($H$7:H19)),IF(ROWS($H$7:H19)-COUNTA($A$7:$A$18)<=COUNTA($C$7:$C$31),INDEX($C$7:$C$31,ROWS($H$7:H19)-COUNTA($A$7:$A$18)),"")) -> สุขภาพ & ประกัน
H20: =IF(ROWS($H$7:H20)<=COUNTA($A$7:$A$18),INDEX($A$7:$A$18,ROWS($H$7:H20)),IF(ROWS($H$7:H20)-COUNTA($A$7:$A$18)<=COUNTA($C$7:$C$31),INDEX($C$7:$C$31,ROWS($H$7:H20)-COUNTA($A$7:$A$18)),"")) -> การศึกษา
H21: =IF(ROWS($H$7:H21)<=COUNTA($A$7:$A$18),INDEX($A$7:$A$18,ROWS($H$7:H21)),IF(ROWS($H$7:H21)-COUNTA($A$7:$A$18)<=COUNTA($C$7:$C$31),INDEX($C$7:$C$31,ROWS($H$7:H21)-COUNTA($A$7:$A$18)),"")) -> บันเทิง & สมาชิกรายเดือน
H22: =IF(ROWS($H$7:H22)<=COUNTA($A$7:$A$18),INDEX($A$7:$A$18,ROWS($H$7:H22)),IF(ROWS($H$7:H22)-COUNTA($A$7:$A$18)<=COUNTA($C$7:$C$31),INDEX($C$7:$C$31,ROWS($H$7:H22)-COUNTA($A$7:$A$18)),"")) -> ครอบครัว
H23: =IF(ROWS($H$7:H23)<=COUNTA($A$7:$A$18),INDEX($A$7:$A$18,ROWS($H$7:H23)),IF(ROWS($H$7:H23)-COUNTA($A$7:$A$18)<=COUNTA($C$7:$C$31),INDEX($C$7:$C$31,ROWS($H$7:H23)-COUNTA($A$7:$A$18)),"")) -> ผ่อนชำระ / หนี้
H24: =IF(ROWS($H$7:H24)<=COUNTA($A$7:$A$18),INDEX($A$7:$A$18,ROWS($H$7:H24)),IF(ROWS($H$7:H24)-COUNTA($A$7:$A$18)<=COUNTA($C$7:$C$31),INDEX($C$7:$C$31,ROWS($H$7:H24)-COUNTA($A$7:$A$18)),"")) -> ออม & ลงทุน
H25: =IF(ROWS($H$7:H25)<=COUNTA($A$7:$A$18),INDEX($A$7:$A$18,ROWS($H$7:H25)),IF(ROWS($H$7:H25)-COUNTA($A$7:$A$18)<=COUNTA($C$7:$C$31),INDEX($C$7:$C$31,ROWS($H$7:H25)-COUNTA($A$7:$A$18)),"")) -> ทำบุญ / ของขวัญ
H26: =IF(ROWS($H$7:H26)<=COUNTA($A$7:$A$18),INDEX($A$7:$A$18,ROWS($H$7:H26)),IF(ROWS($H$7:H26)-COUNTA($A$7:$A$18)<=COUNTA($C$7:$C$31),INDEX($C$7:$C$31,ROWS($H$7:H26)-COUNTA($A$7:$A$18)),"")) -> รายจ่ายอื่น ๆ
H27: =IF(ROWS($H$7:H27)<=COUNTA($A$7:$A$18),INDEX($A$7:$A$18,ROWS($H$7:H27)),IF(ROWS($H$7:H27)-COUNTA($A$7:$A$18)<=COUNTA($C$7:$C$31),INDEX($C$7:$C$31,ROWS($H$7:H27)-COUNTA($A$7:$A$18)),""))
H28: =IF(ROWS($H$7:H28)<=COUNTA($A$7:$A$18),INDEX($A$7:$A$18,ROWS($H$7:H28)),IF(ROWS($H$7:H28)-COUNTA($A$7:$A$18)<=COUNTA($C$7:$C$31),INDEX($C$7:$C$31,ROWS($H$7:H28)-COUNTA($A$7:$A$18)),""))
H29: =IF(ROWS($H$7:H29)<=COUNTA($A$7:$A$18),INDEX($A$7:$A$18,ROWS($H$7:H29)),IF(ROWS($H$7:H29)-COUNTA($A$7:$A$18)<=COUNTA($C$7:$C$31),INDEX($C$7:$C$31,ROWS($H$7:H29)-COUNTA($A$7:$A$18)),""))
H30: =IF(ROWS($H$7:H30)<=COUNTA($A$7:$A$18),INDEX($A$7:$A$18,ROWS($H$7:H30)),IF(ROWS($H$7:H30)-COUNTA($A$7:$A$18)<=COUNTA($C$7:$C$31),INDEX($C$7:$C$31,ROWS($H$7:H30)-COUNTA($A$7:$A$18)),""))
H31: =IF(ROWS($H$7:H31)<=COUNTA($A$7:$A$18),INDEX($A$7:$A$18,ROWS($H$7:H31)),IF(ROWS($H$7:H31)-COUNTA($A$7:$A$18)<=COUNTA($C$7:$C$31),INDEX($C$7:$C$31,ROWS($H$7:H31)-COUNTA($A$7:$A$18)),""))
C32: รวมงบต่อเดือน | D32: =SUM(D7:D31) -> 33800 | H32: =IF(ROWS($H$7:H32)<=COUNTA($A$7:$A$18),INDEX($A$7:$A$18,ROWS($H$7:H32)),IF(ROWS($H$7:H32)-COUNTA($A$7:$A$18)<=COUNTA($C$7:$C$31),INDEX($C$7:$C$31,ROWS($H$7:H32)-COUNTA($A$7:$A$18)),""))
C33: งบประมาณตั้งต้นเป็นตัวอย่าง — ปรับให้ตรงกับรายจ่ายจริงของคุณ | H33: =IF(ROWS($H$7:H33)<=COUNTA($A$7:$A$18),INDEX($A$7:$A$18,ROWS($H$7:H33)),IF(ROWS($H$7:H33)-COUNTA($A$7:$A$18)<=COUNTA($C$7:$C$31),INDEX($C$7:$C$31,ROWS($H$7:H33)-COUNTA($A$7:$A$18)),""))
H34: =IF(ROWS($H$7:H34)<=COUNTA($A$7:$A$18),INDEX($A$7:$A$18,ROWS($H$7:H34)),IF(ROWS($H$7:H34)-COUNTA($A$7:$A$18)<=COUNTA($C$7:$C$31),INDEX($C$7:$C$31,ROWS($H$7:H34)-COUNTA($A$7:$A$18)),""))
H35: =IF(ROWS($H$7:H35)<=COUNTA($A$7:$A$18),INDEX($A$7:$A$18,ROWS($H$7:H35)),IF(ROWS($H$7:H35)-COUNTA($A$7:$A$18)<=COUNTA($C$7:$C$31),INDEX($C$7:$C$31,ROWS($H$7:H35)-COUNTA($A$7:$A$18)),""))
H36: =IF(ROWS($H$7:H36)<=COUNTA($A$7:$A$18),INDEX($A$7:$A$18,ROWS($H$7:H36)),IF(ROWS($H$7:H36)-COUNTA($A$7:$A$18)<=COUNTA($C$7:$C$31),INDEX($C$7:$C$31,ROWS($H$7:H36)-COUNTA($A$7:$A$18)),""))
H37: =IF(ROWS($H$7:H37)<=COUNTA($A$7:$A$18),INDEX($A$7:$A$18,ROWS($H$7:H37)),IF(ROWS($H$7:H37)-COUNTA($A$7:$A$18)<=COUNTA($C$7:$C$31),INDEX($C$7:$C$31,ROWS($H$7:H37)-COUNTA($A$7:$A$18)),""))
H38: =IF(ROWS($H$7:H38)<=COUNTA($A$7:$A$18),INDEX($A$7:$A$18,ROWS($H$7:H38)),IF(ROWS($H$7:H38)-COUNTA($A$7:$A$18)<=COUNTA($C$7:$C$31),INDEX($C$7:$C$31,ROWS($H$7:H38)-COUNTA($A$7:$A$18)),""))
H39: =IF(ROWS($H$7:H39)<=COUNTA($A$7:$A$18),INDEX($A$7:$A$18,ROWS($H$7:H39)),IF(ROWS($H$7:H39)-COUNTA($A$7:$A$18)<=COUNTA($C$7:$C$31),INDEX($C$7:$C$31,ROWS($H$7:H39)-COUNTA($A$7:$A$18)),""))
H40: =IF(ROWS($H$7:H40)<=COUNTA($A$7:$A$18),INDEX($A$7:$A$18,ROWS($H$7:H40)),IF(ROWS($H$7:H40)-COUNTA($A$7:$A$18)<=COUNTA($C$7:$C$31),INDEX($C$7:$C$31,ROWS($H$7:H40)-COUNTA($A$7:$A$18)),""))
...

Sheet บันทึก
A1: บันทึกรายรับรายจ่าย
A2: กรอกเฉพาะคอลัมน์ A–G · คอลัมน์ H เป็นต้นไปคำนวณอัตโนมัติ | J2: ยอดคงเหลือล่าสุด | K2: =ตั้งค่า!B4+SUM(H5:H1004)-SUM(I5:I1004) -> 30382
A4: วันที่ | B4: รายการ | C4: หมวดหมู่ | D4: ประเภท | E4: จำนวนเงิน (฿) | F4: ช่องทางชำระ | G4: หมายเหตุ | H4: รายรับ (฿) | I4: รายจ่าย (฿) | J4: คงเหลือสะสม (฿) | K4: เดือน | L4: ปี
A5: 46290 | B5: เงินเดือนกันยายน | C5: เงินเดือน | D5: =IF(C5="","",IF(COUNTIF(ตั้งค่า!$A$7:$A$18,C5)>0,"รายรับ",IF(COUNTIF(ตั้งค่า!$C$7:$C$31,C5)>0,"รายจ่าย","ไม่พบหมวดหมู่"))) -> รายรับ | E5: 32000 | F5: โอน / พร้อมเพย์ | H5: =IF(OR(E5="",D5<>"รายรับ"),0,E5) -> 32000 | I5: =IF(OR(E5="",D5<>"รายจ่าย"),0,E5) -> 0 | J5: =IF(E5="","",ตั้งค่า!$B$4+SUM($H$5:H5)-SUM($I$5:I5)) -> 47000 | K5: =IF(A5="","",MONTH(A5)) -> 9 | L5: =IF(A5="","",YEAR(A5)) -> 2026
A6: 46291 | B6: ค่าเช่าคอนโด | C6: ที่พัก / ค่าเช่า | D6: =IF(C6="","",IF(COUNTIF(ตั้งค่า!$A$7:$A$18,C6)>0,"รายรับ",IF(COUNTIF(ตั้งค่า!$C$7:$C$31,C6)>0,"รายจ่าย","ไม่พบหมวดหมู่"))) -> รายจ่าย | E6: 8000 | F6: โอน / พร้อมเพย์ | H6: =IF(OR(E6="",D6<>"รายรับ"),0,E6) -> 0 | I6: =IF(OR(E6="",D6<>"รายจ่าย"),0,E6) -> 8000 | J6: =IF(E6="","",ตั้งค่า!$B$4+SUM($H$5:H6)-SUM($I$5:I6)) -> 39000 | K6: =IF(A6="","",MONTH(A6)) -> 9 | L6: =IF(A6="","",YEAR(A6)) -> 2026
A7: 46293 | B7: ซูเปอร์มาร์เก็ต | C7: อาหาร & เครื่องดื่ม | D7: =IF(C7="","",IF(COUNTIF(ตั้งค่า!$A$7:$A$18,C7)>0,"รายรับ",IF(COUNTIF(ตั้งค่า!$C$7:$C$31,C7)>0,"รายจ่าย","ไม่พบหมวดหมู่"))) -> รายจ่าย | E7: 1450 | F7: บัตรเดบิต | H7: =IF(OR(E7="",D7<>"รายรับ"),0,E7) -> 0 | I7: =IF(OR(E7="",D7<>"รายจ่าย"),0,E7) -> 1450 | J7: =IF(E7="","",ตั้งค่า!$B$4+SUM($H$5:H7)-SUM($I$5:I7)) -> 37550 | K7: =IF(A7="","",MONTH(A7)) -> 9 | L7: =IF(A7="","",YEAR(A7)) -> 2026
A8: 46295 | B8: เติมน้ำมัน | C8: เดินทาง / น้ำมัน | D8: =IF(C8="","",IF(COUNTIF(ตั้งค่า!$A$7:$A$18,C8)>0,"รายรับ",IF(COUNTIF(ตั้งค่า!$C$7:$C$31,C8)>0,"รายจ่าย","ไม่พบหมวดหมู่"))) -> รายจ่าย | E8: 1200 | F8: บัตรเครดิต | H8: =IF(OR(E8="",D8<>"รายรับ"),0,E8) -> 0 | I8: =IF(OR(E8="",D8<>"รายจ่าย"),0,E8) -> 1200 | J8: =IF(E8="","",ตั้งค่า!$B$4+SUM($H$5:H8)-SUM($I$5:I8)) -> 36350 | K8: =IF(A8="","",MONTH(A8)) -> 9 | L8: =IF(A8="","",YEAR(A8)) -> 2026
A9: 46296 | B9: ค่าไฟ + ค่าเน็ต | C9: ค่าน้ำ ค่าไฟ ค่าเน็ต | D9: =IF(C9="","",IF(COUNTIF(ตั้งค่า!$A$7:$A$18,C9)>0,"รายรับ",IF(COUNTIF(ตั้งค่า!$C$7:$C$31,C9)>0,"รายจ่าย","ไม่พบหมวดหมู่"))) -> รายจ่าย | E9: 1380 | F9: e-Wallet | G9: บิลเดือน ก.ย. | H9: =IF(OR(E9="",D9<>"รายรับ"),0,E9) -> 0 | I9: =IF(OR(E9="",D9<>"รายจ่าย"),0,E9) -> 1380 | J9: =IF(E9="","",ตั้งค่า!$B$4+SUM($H$5:H9)-SUM($I$5:I9)) -> 34970 | K9: =IF(A9="","",MONTH(A9)) -> 10 | L9: =IF(A9="","",YEAR(A9)) -> 2026
A10: 46298 | B10: งานออกแบบโลโก้ | C10: รายได้เสริม / ฟรีแลนซ์ | D10: =IF(C10="","",IF(COUNTIF(ตั้งค่า!$A$7:$A$18,C10)>0,"รายรับ",IF(COUNTIF(ตั้งค่า!$C$7:$C$31,C10)>0,"รายจ่าย","ไม่พบหมวดหมู่"))) -> รายรับ | E10: 4500 | F10: โอน / พร้อมเพย์ | G10: ลูกค้า A | H10: =IF(OR(E10="",D10<>"รายรับ"),0,E10) -> 4500 | I10: =IF(OR(E10="",D10<>"รายจ่าย"),0,E10) -> 0 | J10: =IF(E10="","",ตั้งค่า!$B$4+SUM($H$5:H10)-SUM($I$5:I10)) -> 39470 | K10: =IF(A10="","",MONTH(A10)) -> 10 | L10: =IF(A10="","",YEAR(A10)) -> 2026
A11: 46300 | B11: ข้าวกลางวันทั้งสัปดาห์ | C11: อาหาร & เครื่องดื่ม | D11: =IF(C11="","",IF(COUNTIF(ตั้งค่า!$A$7:$A$18,C11)>0,"รายรับ",IF(COUNTIF(ตั้งค่า!$C$7:$C$31,C11)>0,"รายจ่าย","ไม่พบหมวดหมู่"))) -> รายจ่าย | E11: 650 | F11: เงินสด | H11: =IF(OR(E11="",D11<>"รายรับ"),0,E11) -> 0 | I11: =IF(OR(E11="",D11<>"รายจ่าย"),0,E11) -> 650 | J11: =IF(E11="","",ตั้งค่า!$B$4+SUM($H$5:H11)-SUM($I$5:I11)) -> 38820 | K11: =IF(A11="","",MONTH(A11)) -> 10 | L11: =IF(A11="","",YEAR(A11)) -> 2026
A12: 46303 | B12: Netflix + Spotify | C12: บันเทิง & สมาชิกรายเดือน | D12: =IF(C12="","",IF(COUNTIF(ตั้งค่า!$A$7:$A$18,C12)>0,"รายรับ",IF(COUNTIF(ตั้งค่า!$C$7:$C$31,C12)>0,"รายจ่าย","ไม่พบหมวดหมู่"))) -> รายจ่าย | E12: 548 | F12: บัตรเครดิต | H12: =IF(OR(E12="",D12<>"รายรับ"),0,E12) -> 0 | I12: =IF(OR(E12="",D12<>"รายจ่าย"),0,E12) -> 548 | J12: =IF(E12="","",ตั้งค่า!$B$4+SUM($H$5:H12)-SUM($I$5:I12)) -> 38272 | K12: =IF(A12="","",MONTH(A12)) -> 10 | L12: =IF(A12="","",YEAR(A12)) -> 2026
A13: 46305 | B13: โอนเข้ากองทุน | C13: ออม & ลงทุน | D13: =IF(C13="","",IF(COUNTIF(ตั้งค่า!$A$7:$A$18,C13)>0,"รายรับ",IF(COUNTIF(ตั้งค่า!$C$7:$C$31,C13)>0,"รายจ่าย","ไม่พบหมวดหมู่"))) -> รายจ่าย | E13: 5000 | F13: โอน / พร้อมเพย์ | G13: DCA รายเดือน | H13: =IF(OR(E13="",D13<>"รายรับ"),0,E13) -> 0 | I13: =IF(OR(E13="",D13<>"รายจ่าย"),0,E13) -> 5000 | J13: =IF(E13="","",ตั้งค่า!$B$4+SUM($H$5:H13)-SUM($I$5:I13)) -> 33272 | K13: =IF(A13="","",MONTH(A13)) -> 10 | L13: =IF(A13="","",YEAR(A13)) -> 2026
A14: 46310 | B14: ซื้อรองเท้าวิ่ง | C14: ช้อปปิ้ง | D14: =IF(C14="","",IF(COUNTIF(ตั้งค่า!$A$7:$A$18,C14)>0,"รายรับ",IF(COUNTIF(ตั้งค่า!$C$7:$C$31,C14)>0,"รายจ่าย","ไม่พบหมวดหมู่"))) -> รายจ่าย | E14: 2890 | F14: บัตรเครดิต | H14: =IF(OR(E14="",D14<>"รายรับ"),0,E14) -> 0 | I14: =IF(OR(E14="",D14<>"รายจ่าย"),0,E14) -> 2890 | J14: =IF(E14="","",ตั้งค่า!$B$4+SUM($H$5:H14)-SUM($I$5:I14)) -> 30382 | K14: =IF(A14="","",MONTH(A14)) -> 10 | L14: =IF(A14="","",YEAR(A14)) -> 2026
D15: =IF(C15="","",IF(COUNTIF(ตั้งค่า!$A$7:$A$18,C15)>0,"รายรับ",IF(COUNTIF(ตั้งค่า!$C$7:$C$31,C15)>0,"รายจ่าย","ไม่พบหมวดหมู่"))) | H15: =IF(OR(E15="",D15<>"รายรับ"),0,E15) -> 0 | I15: =IF(OR(E15="",D15<>"รายจ่าย"),0,E15) -> 0 | J15: =IF(E15="","",ตั้งค่า!$B$4+SUM($H$5:H15)-SUM($I$5:I15)) | K15: =IF(A15="","",MONTH(A15)) | L15: =IF(A15="","",YEAR(A15))
D16: =IF(C16="","",IF(COUNTIF(ตั้งค่า!$A$7:$A$18,C16)>0,"รายรับ",IF(COUNTIF(ตั้งค่า!$C$7:$C$31,C16)>0,"รายจ่าย","ไม่พบหมวดหมู่"))) | H16: =IF(OR(E16="",D16<>"รายรับ"),0,E16) -> 0 | I16: =IF(OR(E16="",D16<>"รายจ่าย"),0,E16) -> 0 | J16: =IF(E16="","",ตั้งค่า!$B$4+SUM($H$5:H16)-SUM($I$5:I16)) | K16: =IF(A16="","",MONTH(A16)) | L16: =IF(A16="","",YEAR(A16))
D17: =IF(C17="","",IF(COUNTIF(ตั้งค่า!$A$7:$A$18,C17)>0,"รายรับ",IF(COUNTIF(ตั้งค่า!$C$7:$C$31,C17)>0,"รายจ่าย","ไม่พบหมวดหมู่"))) | H17: =IF(OR(E17="",D17<>"รายรับ"),0,E17) -> 0 | I17: =IF(OR(E17="",D17<>"รายจ่าย"),0,E17) -> 0 | J17: =IF(E17="","",ตั้งค่า!$B$4+SUM($H$5:H17)-SUM($I$5:I17)) | K17: =IF(A17="","",MONTH(A17)) | L17: =IF(A17="","",YEAR(A17))
D18: =IF(C18="","",IF(COUNTIF(ตั้งค่า!$A$7:$A$18,C18)>0,"รายรับ",IF(COUNTIF(ตั้งค่า!$C$7:$C$31,C18)>0,"รายจ่าย","ไม่พบหมวดหมู่"))) | H18: =IF(OR(E18="",D18<>"รายรับ"),0,E18) -> 0 | I18: =IF(OR(E18="",D18<>"รายจ่าย"),0,E18) -> 0 | J18: =IF(E18="","",ตั้งค่า!$B$4+SUM($H$5:H18)-SUM($I$5:I18)) | K18: =IF(A18="","",MONTH(A18)) | L18: =IF(A18="","",YEAR(A18))
D19: =IF(C19="","",IF(COUNTIF(ตั้งค่า!$A$7:$A$18,C19)>0,"รายรับ",IF(COUNTIF(ตั้งค่า!$C$7:$C$31,C19)>0,"รายจ่าย","ไม่พบหมวดหมู่"))) | H19: =IF(OR(E19="",D19<>"รายรับ"),0,E19) -> 0 | I19: =IF(OR(E19="",D19<>"รายจ่าย"),0,E19) -> 0 | J19: =IF(E19="","",ตั้งค่า!$B$4+SUM($H$5:H19)-SUM($I$5:I19)) | K19: =IF(A19="","",MONTH(A19)) | L19: =IF(A19="","",YEAR(A19))
D20: =IF(C20="","",IF(COUNTIF(ตั้งค่า!$A$7:$A$18,C20)>0,"รายรับ",IF(COUNTIF(ตั้งค่า!$C$7:$C$31,C20)>0,"รายจ่าย","ไม่พบหมวดหมู่"))) | H20: =IF(OR(E20="",D20<>"รายรับ"),0,E20) -> 0 | I20: =IF(OR(E20="",D20<>"รายจ่าย"),0,E20) -> 0 | J20: =IF(E20="","",ตั้งค่า!$B$4+SUM($H$5:H20)-SUM($I$5:I20)) | K20: =IF(A20="","",MONTH(A20)) | L20: =IF(A20="","",YEAR(A20))
D21: =IF(C21="","",IF(COUNTIF(ตั้งค่า!$A$7:$A$18,C21)>0,"รายรับ",IF(COUNTIF(ตั้งค่า!$C$7:$C$31,C21)>0,"รายจ่าย","ไม่พบหมวดหมู่"))) | H21: =IF(OR(E21="",D21<>"รายรับ"),0,E21) -> 0 | I21: =IF(OR(E21="",D21<>"รายจ่าย"),0,E21) -> 0 | J21: =IF(E21="","",ตั้งค่า!$B$4+SUM($H$5:H21)-SUM($I$5:I21)) | K21: =IF(A21="","",MONTH(A21)) | L21: =IF(A21="","",YEAR(A21))
D22: =IF(C22="","",IF(COUNTIF(ตั้งค่า!$A$7:$A$18,C22)>0,"รายรับ",IF(COUNTIF(ตั้งค่า!$C$7:$C$31,C22)>0,"รายจ่าย","ไม่พบหมวดหมู่"))) | H22: =IF(OR(E22="",D22<>"รายรับ"),0,E22) -> 0 | I22: =IF(OR(E22="",D22<>"รายจ่าย"),0,E22) -> 0 | J22: =IF(E22="","",ตั้งค่า!$B$4+SUM($H$5:H22)-SUM($I$5:I22)) | K22: =IF(A22="","",MONTH(A22)) | L22: =IF(A22="","",YEAR(A22))
D23: =IF(C23="","",IF(COUNTIF(ตั้งค่า!$A$7:$A$18,C23)>0,"รายรับ",IF(COUNTIF(ตั้งค่า!$C$7:$C$31,C23)>0,"รายจ่าย","ไม่พบหมวดหมู่"))) | H23: =IF(OR(E23="",D23<>"รายรับ"),0,E23) -> 0 | I23: =IF(OR(E23="",D23<>"รายจ่าย"),0,E23) -> 0 | J23: =IF(E23="","",ตั้งค่า!$B$4+SUM($H$5:H23)-SUM($I$5:I23)) | K23: =IF(A23="","",MONTH(A23)) | L23: =IF(A23="","",YEAR(A23))
D24: =IF(C24="","",IF(COUNTIF(ตั้งค่า!$A$7:$A$18,C24)>0,"รายรับ",IF(COUNTIF(ตั้งค่า!$C$7:$C$31,C24)>0,"รายจ่าย","ไม่พบหมวดหมู่"))) | H24: =IF(OR(E24="",D24<>"รายรับ"),0,E24) -> 0 | I24: =IF(OR(E24="",D24<>"รายจ่าย"),0,E24) -> 0 | J24: =IF(E24="","",ตั้งค่า!$B$4+SUM($H$5:H24)-SUM($I$5:I24)) | K24: =IF(A24="","",MONTH(A24)) | L24: =IF(A24="","",YEAR(A24))
D25: =IF(C25="","",IF(COUNTIF(ตั้งค่า!$A$7:$A$18,C25)>0,"รายรับ",IF(COUNTIF(ตั้งค่า!$C$7:$C$31,C25)>0,"รายจ่าย","ไม่พบหมวดหมู่"))) | H25: =IF(OR(E25="",D25<>"รายรับ"),0,E25) -> 0 | I25: =IF(OR(E25="",D25<>"รายจ่าย"),0,E25) -> 0 | J25: =IF(E25="","",ตั้งค่า!$B$4+SUM($H$5:H25)-SUM($I$5:I25)) | K25: =IF(A25="","",MONTH(A25)) | L25: =IF(A25="","",YEAR(A25))
D26: =IF(C26="","",IF(COUNTIF(ตั้งค่า!$A$7:$A$18,C26)>0,"รายรับ",IF(COUNTIF(ตั้งค่า!$C$7:$C$31,C26)>0,"รายจ่าย","ไม่พบหมวดหมู่"))) | H26: =IF(OR(E26="",D26<>"รายรับ"),0,E26) -> 0 | I26: =IF(OR(E26="",D26<>"รายจ่าย"),0,E26) -> 0 | J26: =IF(E26="","",ตั้งค่า!$B$4+SUM($H$5:H26)-SUM($I$5:I26)) | K26: =IF(A26="","",MONTH(A26)) | L26: =IF(A26="","",YEAR(A26))
... D1004: =IF(C1004="","",IF(COUNTIF(ตั้งค่า!$A$7:$A$18,C1004)>0,"รายรับ",IF(COUNTIF(ตั้งค่า!$C$7:$C$31,C1004)>0,"รายจ่าย","ไม่พบหมวดหมู่"))) | H1004: =IF(OR(E1004="",D1004<>"รายรับ"),0,E1004) -> 0 | I1004: =IF(OR(E1004="",D1004<>"รายจ่าย"),0,E1004) -> 0 | J1004: =IF(E1004="","",ตั้งค่า!$B$4+SUM($H$5:H1004)-SUM($I$5:I1004)) | K1004: =IF(A1004="","",MONTH(A1004)) | L1004: =IF(A1004="","",YEAR(A1004))

Sheet สรุปรายเดือน
A1: สรุปรายเดือน
A2: ="ปี ค.ศ. "&ตั้งค่า!B3&" (พ.ศ. "&ตั้งค่า!B3+543&")" -> ปี ค.ศ. 2026 (พ.ศ. 2569)
A4: เดือน | B4: รายรับ (฿) | C4: รายจ่าย (฿) | D4: คงเหลือสุทธิ (฿) | E4: อัตราการออม | F4: ยอดคงเหลือสะสม (฿) | H4: การ์ดสรุป
A5: มกราคม | B5: =SUMIFS(บันทึก!$H$5:$H$1004,บันทึก!$K$5:$K$1004,1,บันทึก!$L$5:$L$1004,ตั้งค่า!$B$3) -> 0 | C5: =SUMIFS(บันทึก!$I$5:$I$1004,บันทึก!$K$5:$K$1004,1,บันทึก!$L$5:$L$1004,ตั้งค่า!$B$3) -> 0 | D5: =B5-C5 -> 0 | E5: =IF(B5=0,0,D5/B5) -> 0 | F5: =ตั้งค่า!$B$4+SUM($D$5:D5) -> 15000 | H5: รายรับทั้งปี | I5: =B17 -> 36500
A6: กุมภาพันธ์ | B6: =SUMIFS(บันทึก!$H$5:$H$1004,บันทึก!$K$5:$K$1004,2,บันทึก!$L$5:$L$1004,ตั้งค่า!$B$3) -> 0 | C6: =SUMIFS(บันทึก!$I$5:$I$1004,บันทึก!$K$5:$K$1004,2,บันทึก!$L$5:$L$1004,ตั้งค่า!$B$3) -> 0 | D6: =B6-C6 -> 0 | E6: =IF(B6=0,0,D6/B6) -> 0 | F6: =ตั้งค่า!$B$4+SUM($D$5:D6) -> 15000 | H6: รายจ่ายทั้งปี | I6: =C17 -> 21118
A7: มีนาคม | B7: =SUMIFS(บันทึก!$H$5:$H$1004,บันทึก!$K$5:$K$1004,3,บันทึก!$L$5:$L$1004,ตั้งค่า!$B$3) -> 0 | C7: =SUMIFS(บันทึก!$I$5:$I$1004,บันทึก!$K$5:$K$1004,3,บันทึก!$L$5:$L$1004,ตั้งค่า!$B$3) -> 0 | D7: =B7-C7 -> 0 | E7: =IF(B7=0,0,D7/B7) -> 0 | F7: =ตั้งค่า!$B$4+SUM($D$5:D7) -> 15000 | H7: ออมได้ | I7: =D17 -> 15382
A8: เมษายน | B8: =SUMIFS(บันทึก!$H$5:$H$1004,บันทึก!$K$5:$K$1004,4,บันทึก!$L$5:$L$1004,ตั้งค่า!$B$3) -> 0 | C8: =SUMIFS(บันทึก!$I$5:$I$1004,บันทึก!$K$5:$K$1004,4,บันทึก!$L$5:$L$1004,ตั้งค่า!$B$3) -> 0 | D8: =B8-C8 -> 0 | E8: =IF(B8=0,0,D8/B8) -> 0 | F8: =ตั้งค่า!$B$4+SUM($D$5:D8) -> 15000 | H8: อัตราการออม | I8: =E17 -> 0.42142466
A9: พฤษภาคม | B9: =SUMIFS(บันทึก!$H$5:$H$1004,บันทึก!$K$5:$K$1004,5,บันทึก!$L$5:$L$1004,ตั้งค่า!$B$3) -> 0 | C9: =SUMIFS(บันทึก!$I$5:$I$1004,บันทึก!$K$5:$K$1004,5,บันทึก!$L$5:$L$1004,ตั้งค่า!$B$3) -> 0 | D9: =B9-C9 -> 0 | E9: =IF(B9=0,0,D9/B9) -> 0 | F9: =ตั้งค่า!$B$4+SUM($D$5:D9) -> 15000 | H9: เดือนที่ใช้จ่ายมากสุด | I9: =IF(MAX(C5:C16)=0,"-",INDEX(A5:A16,MATCH(MAX(C5:C16),C5:C16,0))) -> กันยายน
A10: มิถุนายน | B10: =SUMIFS(บันทึก!$H$5:$H$1004,บันทึก!$K$5:$K$1004,6,บันทึก!$L$5:$L$1004,ตั้งค่า!$B$3) -> 0 | C10: =SUMIFS(บันทึก!$I$5:$I$1004,บันทึก!$K$5:$K$1004,6,บันทึก!$L$5:$L$1004,ตั้งค่า!$B$3) -> 0 | D10: =B10-C10 -> 0 | E10: =IF(B10=0,0,D10/B10) -> 0 | F10: =ตั้งค่า!$B$4+SUM($D$5:D10) -> 15000 | H10: ยอดคงเหลือปัจจุบัน | I10: =บันทึก!K2 -> 30382
A11: กรกฎาคม | B11: =SUMIFS(บันทึก!$H$5:$H$1004,บันทึก!$K$5:$K$1004,7,บันทึก!$L$5:$L$1004,ตั้งค่า!$B$3) -> 0 | C11: =SUMIFS(บันทึก!$I$5:$I$1004,บันทึก!$K$5:$K$1004,7,บันทึก!$L$5:$L$1004,ตั้งค่า!$B$3) -> 0 | D11: =B11-C11 -> 0 | E11: =IF(B11=0,0,D11/B11) -> 0 | F11: =ตั้งค่า!$B$4+SUM($D$5:D11) -> 15000
A12: สิงหาคม | B12: =SUMIFS(บันทึก!$H$5:$H$1004,บันทึก!$K$5:$K$1004,8,บันทึก!$L$5:$L$1004,ตั้งค่า!$B$3) -> 0 | C12: =SUMIFS(บันทึก!$I$5:$I$1004,บันทึก!$K$5:$K$1004,8,บันทึก!$L$5:$L$1004,ตั้งค่า!$B$3) -> 0 | D12: =B12-C12 -> 0 | E12: =IF(B12=0,0,D12/B12) -> 0 | F12: =ตั้งค่า!$B$4+SUM($D$5:D12) -> 15000
A13: กันยายน | B13: =SUMIFS(บันทึก!$H$5:$H$1004,บันทึก!$K$5:$K$1004,9,บันทึก!$L$5:$L$1004,ตั้งค่า!$B$3) -> 32000 | C13: =SUMIFS(บันทึก!$I$5:$I$1004,บันทึก!$K$5:$K$1004,9,บันทึก!$L$5:$L$1004,ตั้งค่า!$B$3) -> 10650 | D13: =B13-C13 -> 21350 | E13: =IF(B13=0,0,D13/B13) -> 0.6671875 | F13: =ตั้งค่า!$B$4+SUM($D$5:D13) -> 36350
A14: ตุลาคม | B14: =SUMIFS(บันทึก!$H$5:$H$1004,บันทึก!$K$5:$K$1004,10,บันทึก!$L$5:$L$1004,ตั้งค่า!$B$3) -> 4500 | C14: =SUMIFS(บันทึก!$I$5:$I$1004,บันทึก!$K$5:$K$1004,10,บันทึก!$L$5:$L$1004,ตั้งค่า!$B$3) -> 10468 | D14: =B14-C14 -> -5968 | E14: =IF(B14=0,0,D14/B14) -> -1.3262222 | F14: =ตั้งค่า!$B$4+SUM($D$5:D14) -> 30382
A15: พฤศจิกายน | B15: =SUMIFS(บันทึก!$H$5:$H$1004,บันทึก!$K$5:$K$1004,11,บันทึก!$L$5:$L$1004,ตั้งค่า!$B$3) -> 0 | C15: =SUMIFS(บันทึก!$I$5:$I$1004,บันทึก!$K$5:$K$1004,11,บันทึก!$L$5:$L$1004,ตั้งค่า!$B$3) -> 0 | D15: =B15-C15 -> 0 | E15: =IF(B15=0,0,D15/B15) -> 0 | F15: =ตั้งค่า!$B$4+SUM($D$5:D15) -> 30382
A16: ธันวาคม | B16: =SUMIFS(บันทึก!$H$5:$H$1004,บันทึก!$K$5:$K$1004,12,บันทึก!$L$5:$L$1004,ตั้งค่า!$B$3) -> 0 | C16: =SUMIFS(บันทึก!$I$5:$I$1004,บันทึก!$K$5:$K$1004,12,บันทึก!$L$5:$L$1004,ตั้งค่า!$B$3) -> 0 | D16: =B16-C16 -> 0 | E16: =IF(B16=0,0,D16/B16) -> 0 | F16: =ตั้งค่า!$B$4+SUM($D$5:D16) -> 30382
A17: รวมทั้งปี | B17: =SUM(B5:B16) -> 36500 | C17: =SUM(C5:C16) -> 21118 | D17: =B17-C17 -> 15382 | E17: =IF(B17=0,0,D17/B17) -> 0.42142466 | F17: =F16 -> 30382
A18: เฉลี่ยต่อเดือนที่มีรายการ | B18: =IFERROR(B17/COUNTIF(B5:B16,">0"),0) -> 18250 | C18: =IFERROR(C17/COUNTIF(C5:C16,">0"),0) -> 10559

Sheet งบประมาณ
A1: งบประมาณ vs ใช้จริง
A2: เลือกเดือนในช่องพื้นเหลือง
A3: เดือน | B3: ตุลาคม | C3: =MATCH(B3,{"มกราคม","กุมภาพันธ์","มีนาคม","เมษายน","พฤษภาคม","มิถุนายน","กรกฎาคม","สิงหาคม","กันยายน","ตุลาคม","พฤศจิกายน","ธันวาคม"},0) -> 10
A5: หมวดหมู่รายจ่าย | B5: งบ (฿) | C5: ใช้จริง (฿) | D5: คงเหลือ (฿) | E5: % ที่ใช้ | F5: สถานะ
A6: =IF(ตั้งค่า!C7="","",ตั้งค่า!C7) -> อาหาร & เครื่องดื่ม | B6: =IF(A6="","",ตั้งค่า!D7) -> 6000 | C6: =IF(A6="","",SUMIFS(บันทึก!$I$5:$I$1004,บันทึก!$C$5:$C$1004,A6,บันทึก!$K$5:$K$1004,$C$3,บันทึก!$L$5:$L$1004,ตั้งค่า!$B$3)) -> 650 | D6: =IF(A6="","",N(B6)-C6) -> 5350 | E6: =IF(OR(A6="",N(B6)=0),"",C6/B6) -> 0.10833333 | F6: =IF(A6="","",IF(N(B6)=0,IF(C6>0,"ไม่มีงบ","-"),IF(C6>B6,"เกินงบ",IF(C6>=0.8*B6,"ใกล้เต็ม","ปกติ")))) -> ปกติ
A7: =IF(ตั้งค่า!C8="","",ตั้งค่า!C8) -> ที่พัก / ค่าเช่า | B7: =IF(A7="","",ตั้งค่า!D8) -> 8000 | C7: =IF(A7="","",SUMIFS(บันทึก!$I$5:$I$1004,บันทึก!$C$5:$C$1004,A7,บันทึก!$K$5:$K$1004,$C$3,บันทึก!$L$5:$L$1004,ตั้งค่า!$B$3)) -> 0 | D7: =IF(A7="","",N(B7)-C7) -> 8000 | E7: =IF(OR(A7="",N(B7)=0),"",C7/B7) -> 0 | F7: =IF(A7="","",IF(N(B7)=0,IF(C7>0,"ไม่มีงบ","-"),IF(C7>B7,"เกินงบ",IF(C7>=0.8*B7,"ใกล้เต็ม","ปกติ")))) -> ปกติ
A8: =IF(ตั้งค่า!C9="","",ตั้งค่า!C9) -> ค่าน้ำ ค่าไฟ ค่าเน็ต | B8: =IF(A8="","",ตั้งค่า!D9) -> 1500 | C8: =IF(A8="","",SUMIFS(บันทึก!$I$5:$I$1004,บันทึก!$C$5:$C$1004,A8,บันทึก!$K$5:$K$1004,$C$3,บันทึก!$L$5:$L$1004,ตั้งค่า!$B$3)) -> 1380 | D8: =IF(A8="","",N(B8)-C8) -> 120 | E8: =IF(OR(A8="",N(B8)=0),"",C8/B8) -> 0.92 | F8: =IF(A8="","",IF(N(B8)=0,IF(C8>0,"ไม่มีงบ","-"),IF(C8>B8,"เกินงบ",IF(C8>=0.8*B8,"ใกล้เต็ม","ปกติ")))) -> ใกล้เต็ม
A9: =IF(ตั้งค่า!C10="","",ตั้งค่า!C10) -> เดินทาง / น้ำมัน | B9: =IF(A9="","",ตั้งค่า!D10) -> 2500 | C9: =IF(A9="","",SUMIFS(บันทึก!$I$5:$I$1004,บันทึก!$C$5:$C$1004,A9,บันทึก!$K$5:$K$1004,$C$3,บันทึก!$L$5:$L$1004,ตั้งค่า!$B$3)) -> 0 | D9: =IF(A9="","",N(B9)-C9) -> 2500 | E9: =IF(OR(A9="",N(B9)=0),"",C9/B9) -> 0 | F9: =IF(A9="","",IF(N(B9)=0,IF(C9>0,"ไม่มีงบ","-"),IF(C9>B9,"เกินงบ",IF(C9>=0.8*B9,"ใกล้เต็ม","ปกติ")))) -> ปกติ
A10: =IF(ตั้งค่า!C11="","",ตั้งค่า!C11) -> ช้อปปิ้ง | B10: =IF(A10="","",ตั้งค่า!D11) -> 2000 | C10: =IF(A10="","",SUMIFS(บันทึก!$I$5:$I$1004,บันทึก!$C$5:$C$1004,A10,บันทึก!$K$5:$K$1004,$C$3,บันทึก!$L$5:$L$1004,ตั้งค่า!$B$3)) -> 2890 | D10: =IF(A10="","",N(B10)-C10) -> -890 | E10: =IF(OR(A10="",N(B10)=0),"",C10/B10) -> 1.445 | F10: =IF(A10="","",IF(N(B10)=0,IF(C10>0,"ไม่มีงบ","-"),IF(C10>B10,"เกินงบ",IF(C10>=0.8*B10,"ใกล้เต็ม","ปกติ")))) -> เกินงบ
A11: =IF(ตั้งค่า!C12="","",ตั้งค่า!C12) -> สุขภาพ & ประกัน | B11: =IF(A11="","",ตั้งค่า!D12) -> 1000 | C11: =IF(A11="","",SUMIFS(บันทึก!$I$5:$I$1004,บันทึก!$C$5:$C$1004,A11,บันทึก!$K$5:$K$1004,$C$3,บันทึก!$L$5:$L$1004,ตั้งค่า!$B$3)) -> 0 | D11: =IF(A11="","",N(B11)-C11) -> 1000 | E11: =IF(OR(A11="",N(B11)=0),"",C11/B11) -> 0 | F11: =IF(A11="","",IF(N(B11)=0,IF(C11>0,"ไม่มีงบ","-"),IF(C11>B11,"เกินงบ",IF(C11>=0.8*B11,"ใกล้เต็ม","ปกติ")))) -> ปกติ
A12: =IF(ตั้งค่า!C13="","",ตั้งค่า!C13) -> การศึกษา | B12: =IF(A12="","",ตั้งค่า!D13) -> 500 | C12: =IF(A12="","",SUMIFS(บันทึก!$I$5:$I$1004,บันทึก!$C$5:$C$1004,A12,บันทึก!$K$5:$K$1004,$C$3,บันทึก!$L$5:$L$1004,ตั้งค่า!$B$3)) -> 0 | D12: =IF(A12="","",N(B12)-C12) -> 500 | E12: =IF(OR(A12="",N(B12)=0),"",C12/B12) -> 0 | F12: =IF(A12="","",IF(N(B12)=0,IF(C12>0,"ไม่มีงบ","-"),IF(C12>B12,"เกินงบ",IF(C12>=0.8*B12,"ใกล้เต็ม","ปกติ")))) -> ปกติ
A13: =IF(ตั้งค่า!C14="","",ตั้งค่า!C14) -> บันเทิง & สมาชิกรายเดือน | B13: =IF(A13="","",ตั้งค่า!D14) -> 800 | C13: =IF(A13="","",SUMIFS(บันทึก!$I$5:$I$1004,บันทึก!$C$5:$C$1004,A13,บันทึก!$K$5:$K$1004,$C$3,บันทึก!$L$5:$L$1004,ตั้งค่า!$B$3)) -> 548 | D13: =IF(A13="","",N(B13)-C13) -> 252 | E13: =IF(OR(A13="",N(B13)=0),"",C13/B13) -> 0.685 | F13: =IF(A13="","",IF(N(B13)=0,IF(C13>0,"ไม่มีงบ","-"),IF(C13>B13,"เกินงบ",IF(C13>=0.8*B13,"ใกล้เต็ม","ปกติ")))) -> ปกติ
A14: =IF(ตั้งค่า!C15="","",ตั้งค่า!C15) -> ครอบครัว | B14: =IF(A14="","",ตั้งค่า!D15) -> 2000 | C14: =IF(A14="","",SUMIFS(บันทึก!$I$5:$I$1004,บันทึก!$C$5:$C$1004,A14,บันทึก!$K$5:$K$1004,$C$3,บันทึก!$L$5:$L$1004,ตั้งค่า!$B$3)) -> 0 | D14: =IF(A14="","",N(B14)-C14) -> 2000 | E14: =IF(OR(A14="",N(B14)=0),"",C14/B14) -> 0 | F14: =IF(A14="","",IF(N(B14)=0,IF(C14>0,"ไม่มีงบ","-"),IF(C14>B14,"เกินงบ",IF(C14>=0.8*B14,"ใกล้เต็ม","ปกติ")))) -> ปกติ
A15: =IF(ตั้งค่า!C16="","",ตั้งค่า!C16) -> ผ่อนชำระ / หนี้ | B15: =IF(A15="","",ตั้งค่า!D16) -> 3000 | C15: =IF(A15="","",SUMIFS(บันทึก!$I$5:$I$1004,บันทึก!$C$5:$C$1004,A15,บันทึก!$K$5:$K$1004,$C$3,บันทึก!$L$5:$L$1004,ตั้งค่า!$B$3)) -> 0 | D15: =IF(A15="","",N(B15)-C15) -> 3000 | E15: =IF(OR(A15="",N(B15)=0),"",C15/B15) -> 0 | F15: =IF(A15="","",IF(N(B15)=0,IF(C15>0,"ไม่มีงบ","-"),IF(C15>B15,"เกินงบ",IF(C15>=0.8*B15,"ใกล้เต็ม","ปกติ")))) -> ปกติ
A16: =IF(ตั้งค่า!C17="","",ตั้งค่า!C17) -> ออม & ลงทุน | B16: =IF(A16="","",ตั้งค่า!D17) -> 5000 | C16: =IF(A16="","",SUMIFS(บันทึก!$I$5:$I$1004,บันทึก!$C$5:$C$1004,A16,บันทึก!$K$5:$K$1004,$C$3,บันทึก!$L$5:$L$1004,ตั้งค่า!$B$3)) -> 5000 | D16: =IF(A16="","",N(B16)-C16) -> 0 | E16: =IF(OR(A16="",N(B16)=0),"",C16/B16) -> 1 | F16: =IF(A16="","",IF(N(B16)=0,IF(C16>0,"ไม่มีงบ","-"),IF(C16>B16,"เกินงบ",IF(C16>=0.8*B16,"ใกล้เต็ม","ปกติ")))) -> ใกล้เต็ม
A17: =IF(ตั้งค่า!C18="","",ตั้งค่า!C18) -> ทำบุญ / ของขวัญ | B17: =IF(A17="","",ตั้งค่า!D18) -> 500 | C17: =IF(A17="","",SUMIFS(บันทึก!$I$5:$I$1004,บันทึก!$C$5:$C$1004,A17,บันทึก!$K$5:$K$1004,$C$3,บันทึก!$L$5:$L$1004,ตั้งค่า!$B$3)) -> 0 | D17: =IF(A17="","",N(B17)-C17) -> 500 | E17: =IF(OR(A17="",N(B17)=0),"",C17/B17) -> 0 | F17: =IF(A17="","",IF(N(B17)=0,IF(C17>0,"ไม่มีงบ","-"),IF(C17>B17,"เกินงบ",IF(C17>=0.8*B17,"ใกล้เต็ม","ปกติ")))) -> ปกติ
... A30: =IF(ตั้งค่า!C31="","",ตั้งค่า!C31) | B30: =IF(A30="","",ตั้งค่า!D31) | C30: =IF(A30="","",SUMIFS(บันทึก!$I$5:$I$1004,บันทึก!$C$5:$C$1004,A30,บันทึก!$K$5:$K$1004,$C$3,บันทึก!$L$5:$L$1004,ตั้งค่า!$B$3)) | D30: =IF(A30="","",N(B30)-C30) | E30: =IF(OR(A30="",N(B30)=0),"",C30/B30) | F30: =IF(A30="","",IF(N(B30)=0,IF(C30>0,"ไม่มีงบ","-"),IF(C30>B30,"เกินงบ",IF(C30>=0.8*B30,"ใกล้เต็ม","ปกติ"))))
A31: รวม | B31: =SUM(B6:B30) -> 33800 | C31: =SUM(C6:C30) -> 10468 | D31: =B31-C31 -> 23332 | E31: =IF(B31=0,"",C31/B31) -> 0.30970414
A33: รายจ่ายรายหมวดทั้งปี
A34: หมวดหมู่ | B34: ม.ค. | C34: ก.พ. | D34: มี.ค. | E34: เม.ย. | F34: พ.ค. | G34: มิ.ย. | H34: ก.ค. | I34: ส.ค. | J34: ก.ย. | K34: ต.ค. | L34: พ.ย. | M34: ธ.ค. | N34: รวมทั้งปี
A35: =A6 -> อาหาร & เครื่องดื่ม | B35: =IF($A35="","",SUMIFS(บันทึก!$I$5:$I$1004,บันทึก!$C$5:$C$1004,$A35,บันทึก!$K$5:$K$1004,1,บันทึก!$L$5:$L$1004,ตั้งค่า!$B$3)) -> 0 | C35: =IF($A35="","",SUMIFS(บันทึก!$I$5:$I$1004,บันทึก!$C$5:$C$1004,$A35,บันทึก!$K$5:$K$1004,2,บันทึก!$L$5:$L$1004,ตั้งค่า!$B$3)) -> 0 | D35: =IF($A35="","",SUMIFS(บันทึก!$I$5:$I$1004,บันทึก!$C$5:$C$1004,$A35,บันทึก!$K$5:$K$1004,3,บันทึก!$L$5:$L$1004,ตั้งค่า!$B$3)) -> 0 | E35: =IF($A35="","",SUMIFS(บันทึก!$I$5:$I$1004,บันทึก!$C$5:$C$1004,$A35,บันทึก!$K$5:$K$1004,4,บันทึก!$L$5:$L$1004,ตั้งค่า!$B$3)) -> 0 | F35: =IF($A35="","",SUMIFS(บันทึก!$I$5:$I$1004,บันทึก!$C$5:$C$1004,$A35,บันทึก!$K$5:$K$1004,5,บันทึก!$L$5:$L$1004,ตั้งค่า!$B$3)) -> 0 | G35: =IF($A35="","",SUMIFS(บันทึก!$I$5:$I$1004,บันทึก!$C$5:$C$1004,$A35,บันทึก!$K$5:$K$1004,6,บันทึก!$L$5:$L$1004,ตั้งค่า!$B$3)) -> 0 | H35: =IF($A35="","",SUMIFS(บันทึก!$I$5:$I$1004,บันทึก!$C$5:$C$1004,$A35,บันทึก!$K$5:$K$1004,7,บันทึก!$L$5:$L$1004,ตั้งค่า!$B$3)) -> 0 | I35: =IF($A35="","",SUMIFS(บันทึก!$I$5:$I$1004,บันทึก!$C$5:$C$1004,$A35,บันทึก!$K$5:$K$1004,8,บันทึก!$L$5:$L$1004,ตั้งค่า!$B$3)) -> 0 | J35: =IF($A35="","",SUMIFS(บันทึก!$I$5:$I$1004,บันทึก!$C$5:$C$1004,$A35,บันทึก!$K$5:$K$1004,9,บันทึก!$L$5:$L$1004,ตั้งค่า!$B$3)) -> 1450 | K35: =IF($A35="","",SUMIFS(บันทึก!$I$5:$I$1004,บันทึก!$C$5:$C$1004,$A35,บันทึก!$K$5:$K$1004,10,บันทึก!$L$5:$L$1004,ตั้งค่า!$B$3)) -> 650 | L35: =IF($A35="","",SUMIFS(บันทึก!$I$5:$I$1004,บันทึก!$C$5:$C$1004,$A35,บันทึก!$K$5:$K$1004,11,บันทึก!$L$5:$L$1004,ตั้งค่า!$B$3)) -> 0 | M35: =IF($A35="","",SUMIFS(บันทึก!$I$5:$I$1004,บันทึก!$C$5:$C$1004,$A35,บันทึก!$K$5:$K$1004,12,บันทึก!$L$5:$L$1004,ตั้งค่า!$B$3)) -> 0 | N35: =IF($A35="","",SUM(B35:M35)) -> 2100
A36: =A7 -> ที่พัก / ค่าเช่า | B36: =IF($A36="","",SUMIFS(บันทึก!$I$5:$I$1004,บันทึก!$C$5:$C$1004,$A36,บันทึก!$K$5:$K$1004,1,บันทึก!$L$5:$L$1004,ตั้งค่า!$B$3)) -> 0 | C36: =IF($A36="","",SUMIFS(บันทึก!$I$5:$I$1004,บันทึก!$C$5:$C$1004,$A36,บันทึก!$K$5:$K$1004,2,บันทึก!$L$5:$L$1004,ตั้งค่า!$B$3)) -> 0 | D36: =IF($A36="","",SUMIFS(บันทึก!$I$5:$I$1004,บันทึก!$C$5:$C$1004,$A36,บันทึก!$K$5:$K$1004,3,บันทึก!$L$5:$L$1004,ตั้งค่า!$B$3)) -> 0 | E36: =IF($A36="","",SUMIFS(บันทึก!$I$5:$I$1004,บันทึก!$C$5:$C$1004,$A36,บันทึก!$K$5:$K$1004,4,บันทึก!$L$5:$L$1004,ตั้งค่า!$B$3)) -> 0 | F36: =IF($A36="","",SUMIFS(บันทึก!$I$5:$I$1004,บันทึก!$C$5:$C$1004,$A36,บันทึก!$K$5:$K$1004,5,บันทึก!$L$5:$L$1004,ตั้งค่า!$B$3)) -> 0 | G36: =IF($A36="","",SUMIFS(บันทึก!$I$5:$I$1004,บันทึก!$C$5:$C$1004,$A36,บันทึก!$K$5:$K$1004,6,บันทึก!$L$5:$L$1004,ตั้งค่า!$B$3)) -> 0 | H36: =IF($A36="","",SUMIFS(บันทึก!$I$5:$I$1004,บันทึก!$C$5:$C$1004,$A36,บันทึก!$K$5:$K$1004,7,บันทึก!$L$5:$L$1004,ตั้งค่า!$B$3)) -> 0 | I36: =IF($A36="","",SUMIFS(บันทึก!$I$5:$I$1004,บันทึก!$C$5:$C$1004,$A36,บันทึก!$K$5:$K$1004,8,บันทึก!$L$5:$L$1004,ตั้งค่า!$B$3)) -> 0 | J36: =IF($A36="","",SUMIFS(บันทึก!$I$5:$I$1004,บันทึก!$C$5:$C$1004,$A36,บันทึก!$K$5:$K$1004,9,บันทึก!$L$5:$L$1004,ตั้งค่า!$B$3)) -> 8000 | K36: =IF($A36="","",SUMIFS(บันทึก!$I$5:$I$1004,บันทึก!$C$5:$C$1004,$A36,บันทึก!$K$5:$K$1004,10,บันทึก!$L$5:$L$1004,ตั้งค่า!$B$3)) -> 0 | L36: =IF($A36="","",SUMIFS(บันทึก!$I$5:$I$1004,บันทึก!$C$5:$C$1004,$A36,บันทึก!$K$5:$K$1004,11,บันทึก!$L$5:$L$1004,ตั้งค่า!$B$3)) -> 0 | M36: =IF($A36="","",SUMIFS(บันทึก!$I$5:$I$1004,บันทึก!$C$5:$C$1004,$A36,บันทึก!$K$5:$K$1004,12,บันทึก!$L$5:$L$1004,ตั้งค่า!$B$3)) -> 0 | N36: =IF($A36="","",SUM(B36:M36)) -> 8000
A37: =A8 -> ค่าน้ำ ค่าไฟ ค่าเน็ต | B37: =IF($A37="","",SUMIFS(บันทึก!$I$5:$I$1004,บันทึก!$C$5:$C$1004,$A37,บันทึก!$K$5:$K$1004,1,บันทึก!$L$5:$L$1004,ตั้งค่า!$B$3)) -> 0 | C37: =IF($A37="","",SUMIFS(บันทึก!$I$5:$I$1004,บันทึก!$C$5:$C$1004,$A37,บันทึก!$K$5:$K$1004,2,บันทึก!$L$5:$L$1004,ตั้งค่า!$B$3)) -> 0 | D37: =IF($A37="","",SUMIFS(บันทึก!$I$5:$I$1004,บันทึก!$C$5:$C$1004,$A37,บันทึก!$K$5:$K$1004,3,บันทึก!$L$5:$L$1004,ตั้งค่า!$B$3)) -> 0 | E37: =IF($A37="","",SUMIFS(บันทึก!$I$5:$I$1004,บันทึก!$C$5:$C$1004,$A37,บันทึก!$K$5:$K$1004,4,บันทึก!$L$5:$L$1004,ตั้งค่า!$B$3)) -> 0 | F37: =IF($A37="","",SUMIFS(บันทึก!$I$5:$I$1004,บันทึก!$C$5:$C$1004,$A37,บันทึก!$K$5:$K$1004,5,บันทึก!$L$5:$L$1004,ตั้งค่า!$B$3)) -> 0 | G37: =IF($A37="","",SUMIFS(บันทึก!$I$5:$I$1004,บันทึก!$C$5:$C$1004,$A37,บันทึก!$K$5:$K$1004,6,บันทึก!$L$5:$L$1004,ตั้งค่า!$B$3)) -> 0 | H37: =IF($A37="","",SUMIFS(บันทึก!$I$5:$I$1004,บันทึก!$C$5:$C$1004,$A37,บันทึก!$K$5:$K$1004,7,บันทึก!$L$5:$L$1004,ตั้งค่า!$B$3)) -> 0 | I37: =IF($A37="","",SUMIFS(บันทึก!$I$5:$I$1004,บันทึก!$C$5:$C$1004,$A37,บันทึก!$K$5:$K$1004,8,บันทึก!$L$5:$L$1004,ตั้งค่า!$B$3)) -> 0 | J37: =IF($A37="","",SUMIFS(บันทึก!$I$5:$I$1004,บันทึก!$C$5:$C$1004,$A37,บันทึก!$K$5:$K$1004,9,บันทึก!$L$5:$L$1004,ตั้งค่า!$B$3)) -> 0 | K37: =IF($A37="","",SUMIFS(บันทึก!$I$5:$I$1004,บันทึก!$C$5:$C$1004,$A37,บันทึก!$K$5:$K$1004,10,บันทึก!$L$5:$L$1004,ตั้งค่า!$B$3)) -> 1380 | L37: =IF($A37="","",SUMIFS(บันทึก!$I$5:$I$1004,บันทึก!$C$5:$C$1004,$A37,บันทึก!$K$5:$K$1004,11,บันทึก!$L$5:$L$1004,ตั้งค่า!$B$3)) -> 0 | M37: =IF($A37="","",SUMIFS(บันทึก!$I$5:$I$1004,บันทึก!$C$5:$C$1004,$A37,บันทึก!$K$5:$K$1004,12,บันทึก!$L$5:$L$1004,ตั้งค่า!$B$3)) -> 0 | N37: =IF($A37="","",SUM(B37:M37)) -> 1380
A38: =A9 -> เดินทาง / น้ำมัน | B38: =IF($A38="","",SUMIFS(บันทึก!$I$5:$I$1004,บันทึก!$C$5:$C$1004,$A38,บันทึก!$K$5:$K$1004,1,บันทึก!$L$5:$L$1004,ตั้งค่า!$B$3)) -> 0 | C38: =IF($A38="","",SUMIFS(บันทึก!$I$5:$I$1004,บันทึก!$C$5:$C$1004,$A38,บันทึก!$K$5:$K$1004,2,บันทึก!$L$5:$L$1004,ตั้งค่า!$B$3)) -> 0 | D38: =IF($A38="","",SUMIFS(บันทึก!$I$5:$I$1004,บันทึก!$C$5:$C$1004,$A38,บันทึก!$K$5:$K$1004,3,บันทึก!$L$5:$L$1004,ตั้งค่า!$B$3)) -> 0 | E38: =IF($A38="","",SUMIFS(บันทึก!$I$5:$I$1004,บันทึก!$C$5:$C$1004,$A38,บันทึก!$K$5:$K$1004,4,บันทึก!$L$5:$L$1004,ตั้งค่า!$B$3)) -> 0 | F38: =IF($A38="","",SUMIFS(บันทึก!$I$5:$I$1004,บันทึก!$C$5:$C$1004,$A38,บันทึก!$K$5:$K$1004,5,บันทึก!$L$5:$L$1004,ตั้งค่า!$B$3)) -> 0 | G38: =IF($A38="","",SUMIFS(บันทึก!$I$5:$I$1004,บันทึก!$C$5:$C$1004,$A38,บันทึก!$K$5:$K$1004,6,บันทึก!$L$5:$L$1004,ตั้งค่า!$B$3)) -> 0 | H38: =IF($A38="","",SUMIFS(บันทึก!$I$5:$I$1004,บันทึก!$C$5:$C$1004,$A38,บันทึก!$K$5:$K$1004,7,บันทึก!$L$5:$L$1004,ตั้งค่า!$B$3)) -> 0 | I38: =IF($A38="","",SUMIFS(บันทึก!$I$5:$I$1004,บันทึก!$C$5:$C$1004,$A38,บันทึก!$K$5:$K$1004,8,บันทึก!$L$5:$L$1004,ตั้งค่า!$B$3)) -> 0 | J38: =IF($A38="","",SUMIFS(บันทึก!$I$5:$I$1004,บันทึก!$C$5:$C$1004,$A38,บันทึก!$K$5:$K$1004,9,บันทึก!$L$5:$L$1004,ตั้งค่า!$B$3)) -> 1200 | K38: =IF($A38="","",SUMIFS(บันทึก!$I$5:$I$1004,บันทึก!$C$5:$C$1004,$A38,บันทึก!$K$5:$K$1004,10,บันทึก!$L$5:$L$1004,ตั้งค่า!$B$3)) -> 0 | L38: =IF($A38="","",SUMIFS(บันทึก!$I$5:$I$1004,บันทึก!$C$5:$C$1004,$A38,บันทึก!$K$5:$K$1004,11,บันทึก!$L$5:$L$1004,ตั้งค่า!$B$3)) -> 0 | M38: =IF($A38="","",SUMIFS(บันทึก!$I$5:$I$1004,บันทึก!$C$5:$C$1004,$A38,บันทึก!$K$5:$K$1004,12,บันทึก!$L$5:$L$1004,ตั้งค่า!$B$3)) -> 0 | N38: =IF($A38="","",SUM(B38:M38)) -> 1200
A39: =A10 -> ช้อปปิ้ง | B39: =IF($A39="","",SUMIFS(บันทึก!$I$5:$I$1004,บันทึก!$C$5:$C$1004,$A39,บันทึก!$K$5:$K$1004,1,บันทึก!$L$5:$L$1004,ตั้งค่า!$B$3)) -> 0 | C39: =IF($A39="","",SUMIFS(บันทึก!$I$5:$I$1004,บันทึก!$C$5:$C$1004,$A39,บันทึก!$K$5:$K$1004,2,บันทึก!$L$5:$L$1004,ตั้งค่า!$B$3)) -> 0 | D39: =IF($A39="","",SUMIFS(บันทึก!$I$5:$I$1004,บันทึก!$C$5:$C$1004,$A39,บันทึก!$K$5:$K$1004,3,บันทึก!$L$5:$L$1004,ตั้งค่า!$B$3)) -> 0 | E39: =IF($A39="","",SUMIFS(บันทึก!$I$5:$I$1004,บันทึก!$C$5:$C$1004,$A39,บันทึก!$K$5:$K$1004,4,บันทึก!$L$5:$L$1004,ตั้งค่า!$B$3)) -> 0 | F39: =IF($A39="","",SUMIFS(บันทึก!$I$5:$I$1004,บันทึก!$C$5:$C$1004,$A39,บันทึก!$K$5:$K$1004,5,บันทึก!$L$5:$L$1004,ตั้งค่า!$B$3)) -> 0 | G39: =IF($A39="","",SUMIFS(บันทึก!$I$5:$I$1004,บันทึก!$C$5:$C$1004,$A39,บันทึก!$K$5:$K$1004,6,บันทึก!$L$5:$L$1004,ตั้งค่า!$B$3)) -> 0 | H39: =IF($A39="","",SUMIFS(บันทึก!$I$5:$I$1004,บันทึก!$C$5:$C$1004,$A39,บันทึก!$K$5:$K$1004,7,บันทึก!$L$5:$L$1004,ตั้งค่า!$B$3)) -> 0 | I39: =IF($A39="","",SUMIFS(บันทึก!$I$5:$I$1004,บันทึก!$C$5:$C$1004,$A39,บันทึก!$K$5:$K$1004,8,บันทึก!$L$5:$L$1004,ตั้งค่า!$B$3)) -> 0 | J39: =IF($A39="","",SUMIFS(บันทึก!$I$5:$I$1004,บันทึก!$C$5:$C$1004,$A39,บันทึก!$K$5:$K$1004,9,บันทึก!$L$5:$L$1004,ตั้งค่า!$B$3)) -> 0 | K39: =IF($A39="","",SUMIFS(บันทึก!$I$5:$I$1004,บันทึก!$C$5:$C$1004,$A39,บันทึก!$K$5:$K$1004,10,บันทึก!$L$5:$L$1004,ตั้งค่า!$B$3)) -> 2890 | L39: =IF($A39="","",SUMIFS(บันทึก!$I$5:$I$1004,บันทึก!$C$5:$C$1004,$A39,บันทึก!$K$5:$K$1004,11,บันทึก!$L$5:$L$1004,ตั้งค่า!$B$3)) -> 0 | M39: =IF($A39="","",SUMIFS(บันทึก!$I$5:$I$1004,บันทึก!$C$5:$C$1004,$A39,บันทึก!$K$5:$K$1004,12,บันทึก!$L$5:$L$1004,ตั้งค่า!$B$3)) -> 0 | N39: =IF($A39="","",SUM(B39:M39)) -> 2890
A40: =A11 -> สุขภาพ & ประกัน | B40: =IF($A40="","",SUMIFS(บันทึก!$I$5:$I$1004,บันทึก!$C$5:$C$1004,$A40,บันทึก!$K$5:$K$1004,1,บันทึก!$L$5:$L$1004,ตั้งค่า!$B$3)) -> 0 | C40: =IF($A40="","",SUMIFS(บันทึก!$I$5:$I$1004,บันทึก!$C$5:$C$1004,$A40,บันทึก!$K$5:$K$1004,2,บันทึก!$L$5:$L$1004,ตั้งค่า!$B$3)) -> 0 | D40: =IF($A40="","",SUMIFS(บันทึก!$I$5:$I$1004,บันทึก!$C$5:$C$1004,$A40,บันทึก!$K$5:$K$1004,3,บันทึก!$L$5:$L$1004,ตั้งค่า!$B$3)) -> 0 | E40: =IF($A40="","",SUMIFS(บันทึก!$I$5:$I$1004,บันทึก!$C$5:$C$1004,$A40,บันทึก!$K$5:$K$1004,4,บันทึก!$L$5:$L$1004,ตั้งค่า!$B$3)) -> 0 | F40: =IF($A40="","",SUMIFS(บันทึก!$I$5:$I$1004,บันทึก!$C$5:$C$1004,$A40,บันทึก!$K$5:$K$1004,5,บันทึก!$L$5:$L$1004,ตั้งค่า!$B$3)) -> 0 | G40: =IF($A40="","",SUMIFS(บันทึก!$I$5:$I$1004,บันทึก!$C$5:$C$1004,$A40,บันทึก!$K$5:$K$1004,6,บันทึก!$L$5:$L$1004,ตั้งค่า!$B$3)) -> 0 | H40: =IF($A40="","",SUMIFS(บันทึก!$I$5:$I$1004,บันทึก!$C$5:$C$1004,$A40,บันทึก!$K$5:$K$1004,7,บันทึก!$L$5:$L$1004,ตั้งค่า!$B$3)) -> 0 | I40: =IF($A40="","",SUMIFS(บันทึก!$I$5:$I$1004,บันทึก!$C$5:$C$1004,$A40,บันทึก!$K$5:$K$1004,8,บันทึก!$L$5:$L$1004,ตั้งค่า!$B$3)) -> 0 | J40: =IF($A40="","",SUMIFS(บันทึก!$I$5:$I$1004,บันทึก!$C$5:$C$1004,$A40,บันทึก!$K$5:$K$1004,9,บันทึก!$L$5:$L$1004,ตั้งค่า!$B$3)) -> 0 | K40: =IF($A40="","",SUMIFS(บันทึก!$I$5:$I$1004,บันทึก!$C$5:$C$1004,$A40,บันทึก!$K$5:$K$1004,10,บันทึก!$L$5:$L$1004,ตั้งค่า!$B$3)) -> 0 | L40: =IF($A40="","",SUMIFS(บันทึก!$I$5:$I$1004,บันทึก!$C$5:$C$1004,$A40,บันทึก!$K$5:$K$1004,11,บันทึก!$L$5:$L$1004,ตั้งค่า!$B$3)) -> 0 | M40: =IF($A40="","",SUMIFS(บันทึก!$I$5:$I$1004,บันทึก!$C$5:$C$1004,$A40,บันทึก!$K$5:$K$1004,12,บันทึก!$L$5:$L$1004,ตั้งค่า!$B$3)) -> 0 | N40: =IF($A40="","",SUM(B40:M40)) -> 0
A41: =A12 -> การศึกษา | B41: =IF($A41="","",SUMIFS(บันทึก!$I$5:$I$1004,บันทึก!$C$5:$C$1004,$A41,บันทึก!$K$5:$K$1004,1,บันทึก!$L$5:$L$1004,ตั้งค่า!$B$3)) -> 0 | C41: =IF($A41="","",SUMIFS(บันทึก!$I$5:$I$1004,บันทึก!$C$5:$C$1004,$A41,บันทึก!$K$5:$K$1004,2,บันทึก!$L$5:$L$1004,ตั้งค่า!$B$3)) -> 0 | D41: =IF($A41="","",SUMIFS(บันทึก!$I$5:$I$1004,บันทึก!$C$5:$C$1004,$A41,บันทึก!$K$5:$K$1004,3,บันทึก!$L$5:$L$1004,ตั้งค่า!$B$3)) -> 0 | E41: =IF($A41="","",SUMIFS(บันทึก!$I$5:$I$1004,บันทึก!$C$5:$C$1004,$A41,บันทึก!$K$5:$K$1004,4,บันทึก!$L$5:$L$1004,ตั้งค่า!$B$3)) -> 0 | F41: =IF($A41="","",SUMIFS(บันทึก!$I$5:$I$1004,บันทึก!$C$5:$C$1004,$A41,บันทึก!$K$5:$K$1004,5,บันทึก!$L$5:$L$1004,ตั้งค่า!$B$3)) -> 0 | G41: =IF($A41="","",SUMIFS(บันทึก!$I$5:$I$1004,บันทึก!$C$5:$C$1004,$A41,บันทึก!$K$5:$K$1004,6,บันทึก!$L$5:$L$1004,ตั้งค่า!$B$3)) -> 0 | H41: =IF($A41="","",SUMIFS(บันทึก!$I$5:$I$1004,บันทึก!$C$5:$C$1004,$A41,บันทึก!$K$5:$K$1004,7,บันทึก!$L$5:$L$1004,ตั้งค่า!$B$3)) -> 0 | I41: =IF($A41="","",SUMIFS(บันทึก!$I$5:$I$1004,บันทึก!$C$5:$C$1004,$A41,บันทึก!$K$5:$K$1004,8,บันทึก!$L$5:$L$1004,ตั้งค่า!$B$3)) -> 0 | J41: =IF($A41="","",SUMIFS(บันทึก!$I$5:$I$1004,บันทึก!$C$5:$C$1004,$A41,บันทึก!$K$5:$K$1004,9,บันทึก!$L$5:$L$1004,ตั้งค่า!$B$3)) -> 0 | K41: =IF($A41="","",SUMIFS(บันทึก!$I$5:$I$1004,บันทึก!$C$5:$C$1004,$A41,บันทึก!$K$5:$K$1004,10,บันทึก!$L$5:$L$1004,ตั้งค่า!$B$3)) -> 0 | L41: =IF($A41="","",SUMIFS(บันทึก!$I$5:$I$1004,บันทึก!$C$5:$C$1004,$A41,บันทึก!$K$5:$K$1004,11,บันทึก!$L$5:$L$1004,ตั้งค่า!$B$3)) -> 0 | M41: =IF($A41="","",SUMIFS(บันทึก!$I$5:$I$1004,บันทึก!$C$5:$C$1004,$A41,บันทึก!$K$5:$K$1004,12,บันทึก!$L$5:$L$1004,ตั้งค่า!$B$3)) -> 0 | N41: =IF($A41="","",SUM(B41:M41)) -> 0
A42: =A13 -> บันเทิง & สมาชิกรายเดือน | B42: =IF($A42="","",SUMIFS(บันทึก!$I$5:$I$1004,บันทึก!$C$5:$C$1004,$A42,บันทึก!$K$5:$K$1004,1,บันทึก!$L$5:$L$1004,ตั้งค่า!$B$3)) -> 0 | C42: =IF($A42="","",SUMIFS(บันทึก!$I$5:$I$1004,บันทึก!$C$5:$C$1004,$A42,บันทึก!$K$5:$K$1004,2,บันทึก!$L$5:$L$1004,ตั้งค่า!$B$3)) -> 0 | D42: =IF($A42="","",SUMIFS(บันทึก!$I$5:$I$1004,บันทึก!$C$5:$C$1004,$A42,บันทึก!$K$5:$K$1004,3,บันทึก!$L$5:$L$1004,ตั้งค่า!$B$3)) -> 0 | E42: =IF($A42="","",SUMIFS(บันทึก!$I$5:$I$1004,บันทึก!$C$5:$C$1004,$A42,บันทึก!$K$5:$K$1004,4,บันทึก!$L$5:$L$1004,ตั้งค่า!$B$3)) -> 0 | F42: =IF($A42="","",SUMIFS(บันทึก!$I$5:$I$1004,บันทึก!$C$5:$C$1004,$A42,บันทึก!$K$5:$K$1004,5,บันทึก!$L$5:$L$1004,ตั้งค่า!$B$3)) -> 0 | G42: =IF($A42="","",SUMIFS(บันทึก!$I$5:$I$1004,บันทึก!$C$5:$C$1004,$A42,บันทึก!$K$5:$K$1004,6,บันทึก!$L$5:$L$1004,ตั้งค่า!$B$3)) -> 0 | H42: =IF($A42="","",SUMIFS(บันทึก!$I$5:$I$1004,บันทึก!$C$5:$C$1004,$A42,บันทึก!$K$5:$K$1004,7,บันทึก!$L$5:$L$1004,ตั้งค่า!$B$3)) -> 0 | I42: =IF($A42="","",SUMIFS(บันทึก!$I$5:$I$1004,บันทึก!$C$5:$C$1004,$A42,บันทึก!$K$5:$K$1004,8,บันทึก!$L$5:$L$1004,ตั้งค่า!$B$3)) -> 0 | J42: =IF($A42="","",SUMIFS(บันทึก!$I$5:$I$1004,บันทึก!$C$5:$C$1004,$A42,บันทึก!$K$5:$K$1004,9,บันทึก!$L$5:$L$1004,ตั้งค่า!$B$3)) -> 0 | K42: =IF($A42="","",SUMIFS(บันทึก!$I$5:$I$1004,บันทึก!$C$5:$C$1004,$A42,บันทึก!$K$5:$K$1004,10,บันทึก!$L$5:$L$1004,ตั้งค่า!$B$3)) -> 548 | L42: =IF($A42="","",SUMIFS(บันทึก!$I$5:$I$1004,บันทึก!$C$5:$C$1004,$A42,บันทึก!$K$5:$K$1004,11,บันทึก!$L$5:$L$1004,ตั้งค่า!$B$3)) -> 0 | M42: =IF($A42="","",SUMIFS(บันทึก!$I$5:$I$1004,บันทึก!$C$5:$C$1004,$A42,บันทึก!$K$5:$K$1004,12,บันทึก!$L$5:$L$1004,ตั้งค่า!$B$3)) -> 0 | N42: =IF($A42="","",SUM(B42:M42)) -> 548
A43: =A14 -> ครอบครัว | B43: =IF($A43="","",SUMIFS(บันทึก!$I$5:$I$1004,บันทึก!$C$5:$C$1004,$A43,บันทึก!$K$5:$K$1004,1,บันทึก!$L$5:$L$1004,ตั้งค่า!$B$3)) -> 0 | C43: =IF($A43="","",SUMIFS(บันทึก!$I$5:$I$1004,บันทึก!$C$5:$C$1004,$A43,บันทึก!$K$5:$K$1004,2,บันทึก!$L$5:$L$1004,ตั้งค่า!$B$3)) -> 0 | D43: =IF($A43="","",SUMIFS(บันทึก!$I$5:$I$1004,บันทึก!$C$5:$C$1004,$A43,บันทึก!$K$5:$K$1004,3,บันทึก!$L$5:$L$1004,ตั้งค่า!$B$3)) -> 0 | E43: =IF($A43="","",SUMIFS(บันทึก!$I$5:$I$1004,บันทึก!$C$5:$C$1004,$A43,บันทึก!$K$5:$K$1004,4,บันทึก!$L$5:$L$1004,ตั้งค่า!$B$3)) -> 0 | F43: =IF($A43="","",SUMIFS(บันทึก!$I$5:$I$1004,บันทึก!$C$5:$C$1004,$A43,บันทึก!$K$5:$K$1004,5,บันทึก!$L$5:$L$1004,ตั้งค่า!$B$3)) -> 0 | G43: =IF($A43="","",SUMIFS(บันทึก!$I$5:$I$1004,บันทึก!$C$5:$C$1004,$A43,บันทึก!$K$5:$K$1004,6,บันทึก!$L$5:$L$1004,ตั้งค่า!$B$3)) -> 0 | H43: =IF($A43="","",SUMIFS(บันทึก!$I$5:$I$1004,บันทึก!$C$5:$C$1004,$A43,บันทึก!$K$5:$K$1004,7,บันทึก!$L$5:$L$1004,ตั้งค่า!$B$3)) -> 0 | I43: =IF($A43="","",SUMIFS(บันทึก!$I$5:$I$1004,บันทึก!$C$5:$C$1004,$A43,บันทึก!$K$5:$K$1004,8,บันทึก!$L$5:$L$1004,ตั้งค่า!$B$3)) -> 0 | J43: =IF($A43="","",SUMIFS(บันทึก!$I$5:$I$1004,บันทึก!$C$5:$C$1004,$A43,บันทึก!$K$5:$K$1004,9,บันทึก!$L$5:$L$1004,ตั้งค่า!$B$3)) -> 0 | K43: =IF($A43="","",SUMIFS(บันทึก!$I$5:$I$1004,บันทึก!$C$5:$C$1004,$A43,บันทึก!$K$5:$K$1004,10,บันทึก!$L$5:$L$1004,ตั้งค่า!$B$3)) -> 0 | L43: =IF($A43="","",SUMIFS(บันทึก!$I$5:$I$1004,บันทึก!$C$5:$C$1004,$A43,บันทึก!$K$5:$K$1004,11,บันทึก!$L$5:$L$1004,ตั้งค่า!$B$3)) -> 0 | M43: =IF($A43="","",SUMIFS(บันทึก!$I$5:$I$1004,บันทึก!$C$5:$C$1004,$A43,บันทึก!$K$5:$K$1004,12,บันทึก!$L$5:$L$1004,ตั้งค่า!$B$3)) -> 0 | N43: =IF($A43="","",SUM(B43:M43)) -> 0
A44: =A15 -> ผ่อนชำระ / หนี้ | B44: =IF($A44="","",SUMIFS(บันทึก!$I$5:$I$1004,บันทึก!$C$5:$C$1004,$A44,บันทึก!$K$5:$K$1004,1,บันทึก!$L$5:$L$1004,ตั้งค่า!$B$3)) -> 0 | C44: =IF($A44="","",SUMIFS(บันทึก!$I$5:$I$1004,บันทึก!$C$5:$C$1004,$A44,บันทึก!$K$5:$K$1004,2,บันทึก!$L$5:$L$1004,ตั้งค่า!$B$3)) -> 0 | D44: =IF($A44="","",SUMIFS(บันทึก!$I$5:$I$1004,บันทึก!$C$5:$C$1004,$A44,บันทึก!$K$5:$K$1004,3,บันทึก!$L$5:$L$1004,ตั้งค่า!$B$3)) -> 0 | E44: =IF($A44="","",SUMIFS(บันทึก!$I$5:$I$1004,บันทึก!$C$5:$C$1004,$A44,บันทึก!$K$5:$K$1004,4,บันทึก!$L$5:$L$1004,ตั้งค่า!$B$3)) -> 0 | F44: =IF($A44="","",SUMIFS(บันทึก!$I$5:$I$1004,บันทึก!$C$5:$C$1004,$A44,บันทึก!$K$5:$K$1004,5,บันทึก!$L$5:$L$1004,ตั้งค่า!$B$3)) -> 0 | G44: =IF($A44="","",SUMIFS(บันทึก!$I$5:$I$1004,บันทึก!$C$5:$C$1004,$A44,บันทึก!$K$5:$K$1004,6,บันทึก!$L$5:$L$1004,ตั้งค่า!$B$3)) -> 0 | H44: =IF($A44="","",SUMIFS(บันทึก!$I$5:$I$1004,บันทึก!$C$5:$C$1004,$A44,บันทึก!$K$5:$K$1004,7,บันทึก!$L$5:$L$1004,ตั้งค่า!$B$3)) -> 0 | I44: =IF($A44="","",SUMIFS(บันทึก!$I$5:$I$1004,บันทึก!$C$5:$C$1004,$A44,บันทึก!$K$5:$K$1004,8,บันทึก!$L$5:$L$1004,ตั้งค่า!$B$3)) -> 0 | J44: =IF($A44="","",SUMIFS(บันทึก!$I$5:$I$1004,บันทึก!$C$5:$C$1004,$A44,บันทึก!$K$5:$K$1004,9,บันทึก!$L$5:$L$1004,ตั้งค่า!$B$3)) -> 0 | K44: =IF($A44="","",SUMIFS(บันทึก!$I$5:$I$1004,บันทึก!$C$5:$C$1004,$A44,บันทึก!$K$5:$K$1004,10,บันทึก!$L$5:$L$1004,ตั้งค่า!$B$3)) -> 0 | L44: =IF($A44="","",SUMIFS(บันทึก!$I$5:$I$1004,บันทึก!$C$5:$C$1004,$A44,บันทึก!$K$5:$K$1004,11,บันทึก!$L$5:$L$1004,ตั้งค่า!$B$3)) -> 0 | M44: =IF($A44="","",SUMIFS(บันทึก!$I$5:$I$1004,บันทึก!$C$5:$C$1004,$A44,บันทึก!$K$5:$K$1004,12,บันทึก!$L$5:$L$1004,ตั้งค่า!$B$3)) -> 0 | N44: =IF($A44="","",SUM(B44:M44)) -> 0
A45: =A16 -> ออม & ลงทุน | B45: =IF($A45="","",SUMIFS(บันทึก!$I$5:$I$1004,บันทึก!$C$5:$C$1004,$A45,บันทึก!$K$5:$K$1004,1,บันทึก!$L$5:$L$1004,ตั้งค่า!$B$3)) -> 0 | C45: =IF($A45="","",SUMIFS(บันทึก!$I$5:$I$1004,บันทึก!$C$5:$C$1004,$A45,บันทึก!$K$5:$K$1004,2,บันทึก!$L$5:$L$1004,ตั้งค่า!$B$3)) -> 0 | D45: =IF($A45="","",SUMIFS(บันทึก!$I$5:$I$1004,บันทึก!$C$5:$C$1004,$A45,บันทึก!$K$5:$K$1004,3,บันทึก!$L$5:$L$1004,ตั้งค่า!$B$3)) -> 0 | E45: =IF($A45="","",SUMIFS(บันทึก!$I$5:$I$1004,บันทึก!$C$5:$C$1004,$A45,บันทึก!$K$5:$K$1004,4,บันทึก!$L$5:$L$1004,ตั้งค่า!$B$3)) -> 0 | F45: =IF($A45="","",SUMIFS(บันทึก!$I$5:$I$1004,บันทึก!$C$5:$C$1004,$A45,บันทึก!$K$5:$K$1004,5,บันทึก!$L$5:$L$1004,ตั้งค่า!$B$3)) -> 0 | G45: =IF($A45="","",SUMIFS(บันทึก!$I$5:$I$1004,บันทึก!$C$5:$C$1004,$A45,บันทึก!$K$5:$K$1004,6,บันทึก!$L$5:$L$1004,ตั้งค่า!$B$3)) -> 0 | H45: =IF($A45="","",SUMIFS(บันทึก!$I$5:$I$1004,บันทึก!$C$5:$C$1004,$A45,บันทึก!$K$5:$K$1004,7,บันทึก!$L$5:$L$1004,ตั้งค่า!$B$3)) -> 0 | I45: =IF($A45="","",SUMIFS(บันทึก!$I$5:$I$1004,บันทึก!$C$5:$C$1004,$A45,บันทึก!$K$5:$K$1004,8,บันทึก!$L$5:$L$1004,ตั้งค่า!$B$3)) -> 0 | J45: =IF($A45="","",SUMIFS(บันทึก!$I$5:$I$1004,บันทึก!$C$5:$C$1004,$A45,บันทึก!$K$5:$K$1004,9,บันทึก!$L$5:$L$1004,ตั้งค่า!$B$3)) -> 0 | K45: =IF($A45="","",SUMIFS(บันทึก!$I$5:$I$1004,บันทึก!$C$5:$C$1004,$A45,บันทึก!$K$5:$K$1004,10,บันทึก!$L$5:$L$1004,ตั้งค่า!$B$3)) -> 5000 | L45: =IF($A45="","",SUMIFS(บันทึก!$I$5:$I$1004,บันทึก!$C$5:$C$1004,$A45,บันทึก!$K$5:$K$1004,11,บันทึก!$L$5:$L$1004,ตั้งค่า!$B$3)) -> 0 | M45: =IF($A45="","",SUMIFS(บันทึก!$I$5:$I$1004,บันทึก!$C$5:$C$1004,$A45,บันทึก!$K$5:$K$1004,12,บันทึก!$L$5:$L$1004,ตั้งค่า!$B$3)) -> 0 | N45: =IF($A45="","",SUM(B45:M45)) -> 5000
A46: =A17 -> ทำบุญ / ของขวัญ | B46: =IF($A46="","",SUMIFS(บันทึก!$I$5:$I$1004,บันทึก!$C$5:$C$1004,$A46,บันทึก!$K$5:$K$1004,1,บันทึก!$L$5:$L$1004,ตั้งค่า!$B$3)) -> 0 | C46: =IF($A46="","",SUMIFS(บันทึก!$I$5:$I$1004,บันทึก!$C$5:$C$1004,$A46,บันทึก!$K$5:$K$1004,2,บันทึก!$L$5:$L$1004,ตั้งค่า!$B$3)) -> 0 | D46: =IF($A46="","",SUMIFS(บันทึก!$I$5:$I$1004,บันทึก!$C$5:$C$1004,$A46,บันทึก!$K$5:$K$1004,3,บันทึก!$L$5:$L$1004,ตั้งค่า!$B$3)) -> 0 | E46: =IF($A46="","",SUMIFS(บันทึก!$I$5:$I$1004,บันทึก!$C$5:$C$1004,$A46,บันทึก!$K$5:$K$1004,4,บันทึก!$L$5:$L$1004,ตั้งค่า!$B$3)) -> 0 | F46: =IF($A46="","",SUMIFS(บันทึก!$I$5:$I$1004,บันทึก!$C$5:$C$1004,$A46,บันทึก!$K$5:$K$1004,5,บันทึก!$L$5:$L$1004,ตั้งค่า!$B$3)) -> 0 | G46: =IF($A46="","",SUMIFS(บันทึก!$I$5:$I$1004,บันทึก!$C$5:$C$1004,$A46,บันทึก!$K$5:$K$1004,6,บันทึก!$L$5:$L$1004,ตั้งค่า!$B$3)) -> 0 | H46: =IF($A46="","",SUMIFS(บันทึก!$I$5:$I$1004,บันทึก!$C$5:$C$1004,$A46,บันทึก!$K$5:$K$1004,7,บันทึก!$L$5:$L$1004,ตั้งค่า!$B$3)) -> 0 | I46: =IF($A46="","",SUMIFS(บันทึก!$I$5:$I$1004,บันทึก!$C$5:$C$1004,$A46,บันทึก!$K$5:$K$1004,8,บันทึก!$L$5:$L$1004,ตั้งค่า!$B$3)) -> 0 | J46: =IF($A46="","",SUMIFS(บันทึก!$I$5:$I$1004,บันทึก!$C$5:$C$1004,$A46,บันทึก!$K$5:$K$1004,9,บันทึก!$L$5:$L$1004,ตั้งค่า!$B$3)) -> 0 | K46: =IF($A46="","",SUMIFS(บันทึก!$I$5:$I$1004,บันทึก!$C$5:$C$1004,$A46,บันทึก!$K$5:$K$1004,10,บันทึก!$L$5:$L$1004,ตั้งค่า!$B$3)) -> 0 | L46: =IF($A46="","",SUMIFS(บันทึก!$I$5:$I$1004,บันทึก!$C$5:$C$1004,$A46,บันทึก!$K$5:$K$1004,11,บันทึก!$L$5:$L$1004,ตั้งค่า!$B$3)) -> 0 | M46: =IF($A46="","",SUMIFS(บันทึก!$I$5:$I$1004,บันทึก!$C$5:$C$1004,$A46,บันทึก!$K$5:$K$1004,12,บันทึก!$L$5:$L$1004,ตั้งค่า!$B$3)) -> 0 | N46: =IF($A46="","",SUM(B46:M46)) -> 0
... A59: =A30 | B59: =IF($A59="","",SUMIFS(บันทึก!$I$5:$I$1004,บันทึก!$C$5:$C$1004,$A59,บันทึก!$K$5:$K$1004,1,บันทึก!$L$5:$L$1004,ตั้งค่า!$B$3)) | C59: =IF($A59="","",SUMIFS(บันทึก!$I$5:$I$1004,บันทึก!$C$5:$C$1004,$A59,บันทึก!$K$5:$K$1004,2,บันทึก!$L$5:$L$1004,ตั้งค่า!$B$3)) | D59: =IF($A59="","",SUMIFS(บันทึก!$I$5:$I$1004,บันทึก!$C$5:$C$1004,$A59,บันทึก!$K$5:$K$1004,3,บันทึก!$L$5:$L$1004,ตั้งค่า!$B$3)) | E59: =IF($A59="","",SUMIFS(บันทึก!$I$5:$I$1004,บันทึก!$C$5:$C$1004,$A59,บันทึก!$K$5:$K$1004,4,บันทึก!$L$5:$L$1004,ตั้งค่า!$B$3)) | F59: =IF($A59="","",SUMIFS(บันทึก!$I$5:$I$1004,บันทึก!$C$5:$C$1004,$A59,บันทึก!$K$5:$K$1004,5,บันทึก!$L$5:$L$1004,ตั้งค่า!$B$3)) | G59: =IF($A59="","",SUMIFS(บันทึก!$I$5:$I$1004,บันทึก!$C$5:$C$1004,$A59,บันทึก!$K$5:$K$1004,6,บันทึก!$L$5:$L$1004,ตั้งค่า!$B$3)) | H59: =IF($A59="","",SUMIFS(บันทึก!$I$5:$I$1004,บันทึก!$C$5:$C$1004,$A59,บันทึก!$K$5:$K$1004,7,บันทึก!$L$5:$L$1004,ตั้งค่า!$B$3)) | I59: =IF($A59="","",SUMIFS(บันทึก!$I$5:$I$1004,บันทึก!$C$5:$C$1004,$A59,บันทึก!$K$5:$K$1004,8,บันทึก!$L$5:$L$1004,ตั้งค่า!$B$3)) | J59: =IF($A59="","",SUMIFS(บันทึก!$I$5:$I$1004,บันทึก!$C$5:$C$1004,$A59,บันทึก!$K$5:$K$1004,9,บันทึก!$L$5:$L$1004,ตั้งค่า!$B$3)) | K59: =IF($A59="","",SUMIFS(บันทึก!$I$5:$I$1004,บันทึก!$C$5:$C$1004,$A59,บันทึก!$K$5:$K$1004,10,บันทึก!$L$5:$L$1004,ตั้งค่า!$B$3)) | L59: =IF($A59="","",SUMIFS(บันทึก!$I$5:$I$1004,บันทึก!$C$5:$C$1004,$A59,บันทึก!$K$5:$K$1004,11,บันทึก!$L$5:$L$1004,ตั้งค่า!$B$3)) | M59: =IF($A59="","",SUMIFS(บันทึก!$I$5:$I$1004,บันทึก!$C$5:$C$1004,$A59,บันทึก!$K$5:$K$1004,12,บันทึก!$L$5:$L$1004,ตั้งค่า!$B$3)) | N59: =IF($A59="","",SUM(B59:M59))
A60: รวม | B60: =SUM(B35:B59) -> 0 | C60: =SUM(C35:C59) -> 0 | D60: =SUM(D35:D59) -> 0 | E60: =SUM(E35:E59) -> 0 | F60: =SUM(F35:F59) -> 0 | G60: =SUM(G35:G59) -> 0 | H60: =SUM(H35:H59) -> 0 | I60: =SUM(I35:I59) -> 0 | ... N60: =SUM(N35:N59) -> 21118
